Workbook
Name Flag1: INDIRECT('[1]Countries and Timezone'!$E$7)
Name Flag2: INDIRECT('[1]Countries and Timezone'!$E$8)
Name Flag3: INDIRECT('[1]Countries and Timezone'!$E$9)
Name Flag4: INDIRECT('[1]Countries and Timezone'!$E$10)
Name Ranks: OFFSET(Rankings_old!$A$1,0,0,COUNTA(Rankings_old!$A:$A),7)

Sheet Rankings_old
A1: Rank | B1: Name | C1: Total | D1: Group Stage | E1: Play-off teams | F1: Winner | G1: Play-off Stage | H1: SortKey | I1: 240000 | J1: % | K1: Total prize money
A2: =RANK(C2,C$2:C$28) -> 1 | B2: Abel | C2: =SUM(D2:G2) -> 0 | D2: =INDEX('Group Stage'!$I$3:$DL$3,1,MATCH(B2,'Group Stage'!$I$1:$DL$1,0)) -> 0 | E2: =INDEX('Playoff & Winner'!$D$52:$DG$52,1,MATCH(B2,'Playoff & Winner'!$D$2:$DG$2,0)) -> 0 | F2: =INDEX('Playoff & Winner'!$D$52:$DG$52,1,MATCH(B2,'Playoff & Winner'!$D$2:$DG$2,0)+1) -> 0 | G2: =INDEX('Playoff Stage'!$I$3:$DL$3,1,MATCH(B2,'Playoff Stage'!$I$1:$DL$1,0)) -> 0 | H2: =C2*1000000000+D2*1000000+E2*10000+F2*100+G2+(100-COUNTIF($B$2:$B$28,"<"&B2))/1000 -> 0.1 | I2: =I1*J2 -> 96000 | J2: 0.4 | K2: 1st place
A3: =RANK(C3,C$2:C$28) -> 1 | B3: Aleksandr | C3: =SUM(D3:G3) -> 0 | D3: =INDEX('Group Stage'!$I$3:$DL$3,1,MATCH(B3,'Group Stage'!$I$1:$DL$1,0)) -> 0 | E3: =INDEX('Playoff & Winner'!$D$52:$DG$52,1,MATCH(B3,'Playoff & Winner'!$D$2:$DG$2,0)) -> 0 | F3: =INDEX('Playoff & Winner'!$D$52:$DG$52,1,MATCH(B3,'Playoff & Winner'!$D$2:$DG$2,0)+1) -> 0 | G3: =INDEX('Playoff Stage'!$I$3:$DL$3,1,MATCH(B3,'Playoff Stage'!$I$1:$DL$1,0)) -> 0 | H3: =C3*1000000000+D3*1000000+E3*10000+F3*100+G3+(100-COUNTIF($B$2:$B$28,"<"&B3))/1000 -> 0.099 | I3: =I1*J3 -> 48000 | J3: 0.2 | K3: 2nd place
A4: =RANK(C4,C$2:C$28) -> 1 | B4: Ara | C4: =SUM(D4:G4) -> 0 | D4: =INDEX('Group Stage'!$I$3:$DL$3,1,MATCH(B4,'Group Stage'!$I$1:$DL$1,0)) -> 0 | E4: =INDEX('Playoff & Winner'!$D$52:$DG$52,1,MATCH(B4,'Playoff & Winner'!$D$2:$DG$2,0)) -> 0 | F4: =INDEX('Playoff & Winner'!$D$52:$DG$52,1,MATCH(B4,'Playoff & Winner'!$D$2:$DG$2,0)+1) -> 0 | G4: =INDEX('Playoff Stage'!$I$3:$DL$3,1,MATCH(B4,'Playoff Stage'!$I$1:$DL$1,0)) -> 0 | H4: =C4*1000000000+D4*1000000+E4*10000+F4*100+G4+(100-COUNTIF($B$2:$B$28,"<"&B4))/1000 -> 0.098 | I4: =I1*J4 -> 36000 | J4: 0.15 | K4: 3rd place
A5: =RANK(C5,C$2:C$28) -> 1 | B5: Aram GM | C5: =SUM(D5:G5) -> 0 | D5: =INDEX('Group Stage'!$I$3:$DL$3,1,MATCH(B5,'Group Stage'!$I$1:$DL$1,0)) -> 0 | E5: =INDEX('Playoff & Winner'!$D$52:$DG$52,1,MATCH(B5,'Playoff & Winner'!$D$2:$DG$2,0)) -> 0 | F5: =INDEX('Playoff & Winner'!$D$52:$DG$52,1,MATCH(B5,'Playoff & Winner'!$D$2:$DG$2,0)+1) -> 0 | G5: =INDEX('Playoff Stage'!$I$3:$DL$3,1,MATCH(B5,'Playoff Stage'!$I$1:$DL$1,0)) -> 0 | H5: =C5*1000000000+D5*1000000+E5*10000+F5*100+G5+(100-COUNTIF($B$2:$B$28,"<"&B5))/1000 -> 0.097 | I5: =I1*J5 -> 24000 | J5: 0.1 | K5: 4th place
A6: =RANK(C6,C$2:C$28) -> 1 | B6: Aram Tsh. | C6: =SUM(D6:G6) -> 0 | D6: =INDEX('Group Stage'!$I$3:$DL$3,1,MATCH(B6,'Group Stage'!$I$1:$DL$1,0)) -> 0 | E6: =INDEX('Playoff & Winner'!$D$52:$DG$52,1,MATCH(B6,'Playoff & Winner'!$D$2:$DG$2,0)) -> 0 | F6: =INDEX('Playoff & Winner'!$D$52:$DG$52,1,MATCH(B6,'Playoff & Winner'!$D$2:$DG$2,0)+1) -> 0 | G6: =INDEX('Playoff Stage'!$I$3:$DL$3,1,MATCH(B6,'Playoff Stage'!$I$1:$DL$1,0)) -> 0 | H6: =C6*1000000000+D6*1000000+E6*10000+F6*100+G6+(100-COUNTIF($B$2:$B$28,"<"&B6))/1000 -> 0.096 | I6: =I1*J6 -> 16800 | J6: 0.07 | K6: 5th place
A7: =RANK(C7,C$2:C$28) -> 1 | B7: Arsen | C7: =SUM(D7:G7) -> 0 | D7: =INDEX('Group Stage'!$I$3:$DL$3,1,MATCH(B7,'Group Stage'!$I$1:$DL$1,0)) -> 0 | E7: =INDEX('Playoff & Winner'!$D$52:$DG$52,1,MATCH(B7,'Playoff & Winner'!$D$2:$DG$2,0)) -> 0 | F7: =INDEX('Playoff & Winner'!$D$52:$DG$52,1,MATCH(B7,'Playoff & Winner'!$D$2:$DG$2,0)+1) -> 0 | G7: =INDEX('Playoff Stage'!$I$3:$DL$3,1,MATCH(B7,'Playoff Stage'!$I$1:$DL$1,0)) -> 0 | H7: =C7*1000000000+D7*1000000+E7*10000+F7*100+G7+(100-COUNTIF($B$2:$B$28,"<"&B7))/1000 -> 0.095 | I7: =I1*J7 -> 12000 | J7: 0.05 | K7: 6th place
A8: =RANK(C8,C$2:C$28) -> 1 | B8: Art Cap | C8: =SUM(D8:G8) -> 0 | D8: =INDEX('Group Stage'!$I$3:$DL$3,1,MATCH(B8,'Group Stage'!$I$1:$DL$1,0)) -> 0 | E8: =INDEX('Playoff & Winner'!$D$52:$DG$52,1,MATCH(B8,'Playoff & Winner'!$D$2:$DG$2,0)) -> 0 | F8: =INDEX('Playoff & Winner'!$D$52:$DG$52,1,MATCH(B8,'Playoff & Winner'!$D$2:$DG$2,0)+1) -> 0 | G8: =INDEX('Playoff Stage'!$I$3:$DL$3,1,MATCH(B8,'Playoff Stage'!$I$1:$DL$1,0)) -> 0 | H8: =C8*1000000000+D8*1000000+E8*10000+F8*100+G8+(100-COUNTIF($B$2:$B$28,"<"&B8))/1000 -> 0.094 | I8: =I1*J8 -> 7200 | J8: 0.03 | K8: 7th place
A9: =RANK(C9,C$2:C$28) -> 1 | B9: Art Doc | C9: =SUM(D9:G9) -> 0 | D9: =INDEX('Group Stage'!$I$3:$DL$3,1,MATCH(B9,'Group Stage'!$I$1:$DL$1,0)) -> 0 | E9: =INDEX('Playoff & Winner'!$D$52:$DG$52,1,MATCH(B9,'Playoff & Winner'!$D$2:$DG$2,0)) -> 0 | F9: =INDEX('Playoff & Winner'!$D$52:$DG$52,1,MATCH(B9,'Playoff & Winner'!$D$2:$DG$2,0)+1) -> 0 | G9: =INDEX('Playoff Stage'!$I$3:$DL$3,1,MATCH(B9,'Playoff Stage'!$I$1:$DL$1,0)) -> 0 | H9: =C9*1000000000+D9*1000000+E9*10000+F9*100+G9+(100-COUNTIF($B$2:$B$28,"<"&B9))/1000 -> 0.093
A10: =RANK(C10,C$2:C$28) -> 1 | B10: Davit | C10: =SUM(D10:G10) -> 0 | D10: =INDEX('Group Stage'!$I$3:$DL$3,1,MATCH(B10,'Group Stage'!$I$1:$DL$1,0)) -> 0 | E10: =INDEX('Playoff & Winner'!$D$52:$DG$52,1,MATCH(B10,'Playoff & Winner'!$D$2:$DG$2,0)) -> 0 | F10: =INDEX('Playoff & Winner'!$D$52:$DG$52,1,MATCH(B10,'Playoff & Winner'!$D$2:$DG$2,0)+1) -> 0 | G10: =INDEX('Playoff Stage'!$I$3:$DL$3,1,MATCH(B10,'Playoff Stage'!$I$1:$DL$1,0)) -> 0 | H10: =C10*1000000000+D10*1000000+E10*10000+F10*100+G10+(100-COUNTIF($B$2:$B$28,"<"&B10))/1000 -> 0.092
A11: =RANK(C11,C$2:C$28) -> 1 | B11: Edgar H. | C11: =SUM(D11:G11) -> 0 | D11: =INDEX('Group Stage'!$I$3:$DL$3,1,MATCH(B11,'Group Stage'!$I$1:$DL$1,0)) -> 0 | E11: =INDEX('Playoff & Winner'!$D$52:$DG$52,1,MATCH(B11,'Playoff & Winner'!$D$2:$DG$2,0)) -> 0 | F11: =INDEX('Playoff & Winner'!$D$52:$DG$52,1,MATCH(B11,'Playoff & Winner'!$D$2:$DG$2,0)+1) -> 0 | G11: =INDEX('Playoff Stage'!$I$3:$DL$3,1,MATCH(B11,'Playoff Stage'!$I$1:$DL$1,0)) -> 0 | H11: =C11*1000000000+D11*1000000+E11*10000+F11*100+G11+(100-COUNTIF($B$2:$B$28,"<"&B11))/1000 -> 0.091
A12: =RANK(C12,C$2:C$28) -> 1 | B12: Edgar M. | C12: =SUM(D12:G12) -> 0 | D12: =INDEX('Group Stage'!$I$3:$DL$3,1,MATCH(B12,'Group Stage'!$I$1:$DL$1,0)) -> 0 | E12: =INDEX('Playoff & Winner'!$D$52:$DG$52,1,MATCH(B12,'Playoff & Winner'!$D$2:$DG$2,0)) -> 0 | F12: =INDEX('Playoff & Winner'!$D$52:$DG$52,1,MATCH(B12,'Playoff & Winner'!$D$2:$DG$2,0)+1) -> 0 | G12: =INDEX('Playoff Stage'!$I$3:$DL$3,1,MATCH(B12,'Playoff Stage'!$I$1:$DL$1,0)) -> 0 | H12: =C12*1000000000+D12*1000000+E12*10000+F12*100+G12+(100-COUNTIF($B$2:$B$28,"<"&B12))/1000 -> 0.09
A13: =RANK(C13,C$2:C$28) -> 1 | B13: Gagik St. | C13: =SUM(D13:G13) -> 0 | D13: =INDEX('Group Stage'!$I$3:$DL$3,1,MATCH(B13,'Group Stage'!$I$1:$DL$1,0)) -> 0 | E13: =INDEX('Playoff & Winner'!$D$52:$DG$52,1,MATCH(B13,'Playoff & Winner'!$D$2:$DG$2,0)) -> 0 | F13: =INDEX('Playoff & Winner'!$D$52:$DG$52,1,MATCH(B13,'Playoff & Winner'!$D$2:$DG$2,0)+1) -> 0 | G13: =INDEX('Playoff Stage'!$I$3:$DL$3,1,MATCH(B13,'Playoff Stage'!$I$1:$DL$1,0)) -> 0 | H13: =C13*1000000000+D13*1000000+E13*10000+F13*100+G13+(100-COUNTIF($B$2:$B$28,"<"&B13))/1000 -> 0.088
A14: =RANK(C14,C$2:C$28) -> 1 | B14: Hayk St. | C14: =SUM(D14:G14) -> 0 | D14: =INDEX('Group Stage'!$I$3:$DL$3,1,MATCH(B14,'Group Stage'!$I$1:$DL$1,0)) -> 0 | E14: =INDEX('Playoff & Winner'!$D$52:$DG$52,1,MATCH(B14,'Playoff & Winner'!$D$2:$DG$2,0)) -> 0 | F14: =INDEX('Playoff & Winner'!$D$52:$DG$52,1,MATCH(B14,'Playoff & Winner'!$D$2:$DG$2,0)+1) -> 0 | G14: =INDEX('Playoff Stage'!$I$3:$DL$3,1,MATCH(B14,'Playoff Stage'!$I$1:$DL$1,0)) -> 0 | H14: =C14*1000000000+D14*1000000+E14*10000+F14*100+G14+(100-COUNTIF($B$2:$B$28,"<"&B14))/1000 -> 0.087
A15: =RANK(C15,C$2:C$28) -> 1 | B15: Henrik | C15: =SUM(D15:G15) -> 0 | D15: =INDEX('Group Stage'!$I$3:$DL$3,1,MATCH(B15,'Group Stage'!$I$1:$DL$1,0)) -> 0 | E15: =INDEX('Playoff & Winner'!$D$52:$DG$52,1,MATCH(B15,'Playoff & Winner'!$D$2:$DG$2,0)) -> 0 | F15: =INDEX('Playoff & Winner'!$D$52:$DG$52,1,MATCH(B15,'Playoff & Winner'!$D$2:$DG$2,0)+1) -> 0 | G15: =INDEX('Playoff Stage'!$I$3:$DL$3,1,MATCH(B15,'Playoff Stage'!$I$1:$DL$1,0)) -> 0 | H15: =C15*1000000000+D15*1000000+E15*10000+F15*100+G15+(100-COUNTIF($B$2:$B$28,"<"&B15))/1000 -> 0.086
A16: =RANK(C16,C$2:C$28) -> 1 | B16: Hovo St. | C16: =SUM(D16:G16) -> 0 | D16: =INDEX('Group Stage'!$I$3:$DL$3,1,MATCH(B16,'Group Stage'!$I$1:$DL$1,0)) -> 0 | E16: =INDEX('Playoff & Winner'!$D$52:$DG$52,1,MATCH(B16,'Playoff & Winner'!$D$2:$DG$2,0)) -> 0 | F16: =INDEX('Playoff & Winner'!$D$52:$DG$52,1,MATCH(B16,'Playoff & Winner'!$D$2:$DG$2,0)+1) -> 0 | G16: =INDEX('Playoff Stage'!$I$3:$DL$3,1,MATCH(B16,'Playoff Stage'!$I$1:$DL$1,0)) -> 0 | H16: =C16*1000000000+D16*1000000+E16*10000+F16*100+G16+(100-COUNTIF($B$2:$B$28,"<"&B16))/1000 -> 0.085
A17: =RANK(C17,C$2:C$28) -> 1 | B17: Konstantin | C17: =SUM(D17:G17) -> 0 | D17: =INDEX('Group Stage'!$I$3:$DL$3,1,MATCH(B17,'Group Stage'!$I$1:$DL$1,0)) -> 0 | E17: =INDEX('Playoff & Winner'!$D$52:$DG$52,1,MATCH(B17,'Playoff & Winner'!$D$2:$DG$2,0)) -> 0 | F17: =INDEX('Playoff & Winner'!$D$52:$DG$52,1,MATCH(B17,'Playoff & Winner'!$D$2:$DG$2,0)+1) -> 0 | G17: =INDEX('Playoff Stage'!$I$3:$DL$3,1,MATCH(B17,'Playoff Stage'!$I$1:$DL$1,0)) -> 0 | H17: =C17*1000000000+D17*1000000+E17*10000+F17*100+G17+(100-COUNTIF($B$2:$B$28,"<"&B17))/1000 -> 0.084
A18: =RANK(C18,C$2:C$28) -> 1 | B18: Levon M. | C18: =SUM(D18:G18) -> 0 | D18: =INDEX('Group Stage'!$I$3:$DL$3,1,MATCH(B18,'Group Stage'!$I$1:$DL$1,0)) -> 0 | E18: =INDEX('Playoff & Winner'!$D$52:$DG$52,1,MATCH(B18,'Playoff & Winner'!$D$2:$DG$2,0)) -> 0 | F18: =INDEX('Playoff & Winner'!$D$52:$DG$52,1,MATCH(B18,'Playoff & Winner'!$D$2:$DG$2,0)+1) -> 0 | G18: =INDEX('Playoff Stage'!$I$3:$DL$3,1,MATCH(B18,'Playoff Stage'!$I$1:$DL$1,0)) -> 0 | H18: =C18*1000000000+D18*1000000+E18*10000+F18*100+G18+(100-COUNTIF($B$2:$B$28,"<"&B18))/1000 -> 0.083
A19: =RANK(C19,C$2:C$28) -> 1 | B19: Levon T. | C19: =SUM(D19:G19) -> 0 | D19: =INDEX('Group Stage'!$I$3:$DL$3,1,MATCH(B19,'Group Stage'!$I$1:$DL$1,0)) -> 0 | E19: =INDEX('Playoff & Winner'!$D$52:$DG$52,1,MATCH(B19,'Playoff & Winner'!$D$2:$DG$2,0)) -> 0 | F19: =INDEX('Playoff & Winner'!$D$52:$DG$52,1,MATCH(B19,'Playoff & Winner'!$D$2:$DG$2,0)+1) -> 0 | G19: =INDEX('Playoff Stage'!$I$3:$DL$3,1,MATCH(B19,'Playoff Stage'!$I$1:$DL$1,0)) -> 0 | H19: =C19*1000000000+D19*1000000+E19*10000+F19*100+G19+(100-COUNTIF($B$2:$B$28,"<"&B19))/1000 -> 0.082
A20: =RANK(C20,C$2:C$28) -> 1 | B20: Mark | C20: =SUM(D20:G20) -> 0 | D20: =INDEX('Group Stage'!$I$3:$DL$3,1,MATCH(B20,'Group Stage'!$I$1:$DL$1,0)) -> 0 | E20: =INDEX('Playoff & Winner'!$D$52:$DG$52,1,MATCH(B20,'Playoff & Winner'!$D$2:$DG$2,0)) -> 0 | F20: =INDEX('Playoff & Winner'!$D$52:$DG$52,1,MATCH(B20,'Playoff & Winner'!$D$2:$DG$2,0)+1) -> 0 | G20: =INDEX('Playoff Stage'!$I$3:$DL$3,1,MATCH(B20,'Playoff Stage'!$I$1:$DL$1,0)) -> 0 | H20: =C20*1000000000+D20*1000000+E20*10000+F20*100+G20+(100-COUNTIF($B$2:$B$28,"<"&B20))/1000 -> 0.081
... A28: =RANK(C28,C$2:C$28) -> 1 | B28: Edmon | C28: =SUM(D28:G28) -> 0 | D28: =INDEX('Group Stage'!$I$3:$DL$3,1,MATCH(B28,'Group Stage'!$I$1:$DL$1,0)) -> 0 | E28: =INDEX('Playoff & Winner'!$D$52:$DG$52,1,MATCH(B28,'Playoff & Winner'!$D$2:$DG$2,0)) -> 0 | F28: =INDEX('Playoff & Winner'!$D$52:$DG$52,1,MATCH(B28,'Playoff & Winner'!$D$2:$DG$2,0)+1) -> 0 | G28: =INDEX('Playoff Stage'!$I$3:$DL$3,1,MATCH(B28,'Playoff Stage'!$I$1:$DL$1,0)) -> 0 | H28: =C28*1000000000+D28*1000000+E28*10000+F28*100+G28+(100-COUNTIF($B$2:$B$28,"<"&B28))/1000 -> 0.089
A29: =RANK(C29,C$2:C$28) -> 1 | B29: Minas | C29: =SUM(D29:G29) -> 0 | D29: =INDEX('Group Stage'!$I$3:$DO$3,1,MATCH(B29,'Group Stage'!$I$1:$DO$1,0)) -> 0 | E29: =INDEX('Playoff & Winner'!$D$52:$DK$52,1,MATCH(B29,'Playoff & Winner'!$D$2:$DK$2,0)) -> 0 | F29: =INDEX('Playoff & Winner'!$D$52:$DK$52,1,MATCH(B29,'Playoff & Winner'!$D$2:$DK$2,0)+1) -> 0 | G29: =INDEX('Playoff Stage'!$I$3:$DO$3,1,MATCH(B29,'Playoff Stage'!$I$1:$DO$1,0)) -> 0 | H29: =C29*1000000000+D29*1000000+E29*10000+F29*100+G29+(100-COUNTIF($B$2:$B$28,"<"&B29))/1000 -> 0.08

Sheet Rankings
A1: Rank | B1: Name | C1: Total | D1: Group Stage | E1: Play-off teams | F1: Play-off Stage | G1: Winner
A2: 1 | B2: Abel | C2: 0 | D2: 0 | E2: 0 | F2: 0 | G2: 0
B3: Ara | C3: 0 | D3: 0 | E3: 0 | F3: 0 | G3: 0 | J3: Total Award | K3: 280000 | L3: %
B4: Aram GM | C4: 0 | D4: 0 | E4: 0 | F4: 0 | G4: 0 | J4: 1st place | K4: =K3*L4 -> 112000 | L4: 0.4
B5: Arsen | C5: 0 | D5: 0 | E5: 0 | F5: 0 | G5: 0 | J5: 2nd place | K5: =K3*L5 -> 56000 | L5: 0.2
B6: Gagik St. | C6: 0 | D6: 0 | E6: 0 | F6: 0 | G6: 0 | J6: 3rd place | K6: =K3*L6 -> 42000 | L6: 0.15
B7: Hayk St. | C7: 0 | D7: 0 | E7: 0 | F7: 0 | G7: 0 | J7: 4th place | K7: =K3*L7 -> 28000 | L7: 0.1
B8: Hovo St. | C8: 0 | D8: 0 | E8: 0 | F8: 0 | G8: 0 | J8: 5th place | K8: =K3*L8 -> 19600 | L8: 0.07
B9: Minas | C9: 0 | D9: 0 | E9: 0 | F9: 0 | G9: 0 | J9: 6th place | K9: =K3*L9 -> 14000 | L9: 0.05
B10: Sipan | C10: 0 | D10: 0 | E10: 0 | F10: 0 | G10: 0 | J10: 7th place | K10: =K3*L10 -> 8400 | L10: 0.03
B11: Tigran Tsh. | C11: 0 | D11: 0 | E11: 0 | F11: 0 | G11: 0
B12: Vigen | C12: 0 | D12: 0 | E12: 0 | F12: 0 | G12: 0
B13: Art Doc | C13: 0 | D13: 0 | E13: 0 | F13: 0 | G13: 0
B14: Henrik | C14: 0 | D14: 0 | E14: 0 | F14: 0 | G14: 0
B15: Tigran H. | C15: 0 | D15: 0 | E15: 0 | F15: 0 | G15: 0
B16: Edgar M. | C16: 0 | D16: 0 | E16: 0 | F16: 0 | G16: 0
B17: Edgar H. | C17: 0 | D17: 0 | E17: 0 | F17: 0 | G17: 0
B18: Aleksandr | C18: 0 | D18: 0 | E18: 0 | F18: 0 | G18: 0
B19: Aram Tsh. | C19: 0 | D19: 0 | E19: 0 | F19: 0 | G19: 0
B20: Art Cap | C20: 0 | D20: 0 | E20: 0 | F20: 0 | G20: 0
B21: Davit | C21: 0 | D21: 0 | E21: 0 | F21: 0 | G21: 0
B22: Konstantin | C22: 0 | D22: 0 | E22: 0 | F22: 0 | G22: 0
... B29: Edmon | C29: 0 | D29: 0 | E29: 0 | F29: 0 | G29: 0

Sheet Names
B1: Names
A2: 1 | B2: Abel
A3: 2 | B3: Aleksandr
A4: 3 | B4: Ara
A5: 4 | B5: Aram GM
A6: 5 | B6: Aram Tsh.
A7: 6 | B7: Arsen
A8: 7 | B8: Art Cap
A9: 8 | B9: Art Doc
A10: 9 | B10: Davit
A11: 10 | B11: Edgar H.
A12: 11 | B12: Edgar M.
A13: 12 | B13: Gagik St.
... A28: 27 | B28: Edmon
C36: Abel | D36: Aleksandr | E36: Ara | F36: Aram GM | G36: Aram Tsh. | H36: Arsen | I36: Art Cap | J36: Art Doc | K36: Davit | L36: Edgar H. | M36: Edgar M. | N36: Gagik St. | O36: Hayk St. | P36: Henrik | Q36: Hovo St. | R36: Konstantin | S36: Levon M. | T36: Levon T. | U36: Mark | V36: Rench | W36: Ruben | X36: Sipan | Y36: Tigran Gr. | Z36: Tigran H. | AA36: Tigran Tsh. | AB36: Vigen
B41: Mexico
B42: South Africa
B43: South Korea
B44: Czech Republic
B45: Canada
B46: Bosnia and Herzegovina
B47: Qatar
B48: Switzerland
B49: Brazil
B50: Morocco
B51: Haiti
B52: Scotland
... B88: Panama

Sheet Group Stage
A1: Date&Time | C1: Matches | E1: TOTAL | F1: Actual scores | H1: outcome | I1: Abel | M1: Aleksandr | Q1: Ara | U1: Aram GM | Y1: Aram Tsh. | AC1: Arsen | AG1: Art Cap | AK1: Art Doc | AO1: Davit | AS1: Edgar H. | AW1: Edgar M. | BA1: Gagik St. | BE1: Hayk St. | BI1: Henrik | BM1: Hovo St. | BQ1: Konstantin | BU1: Levon M. | BY1: Levon T. | CC1: Mark | CG1: Rench | CK1: Ruben | CO1: Sipan | CS1: Tigran Gr. | CW1: Tigran H. | DA1: Tigran Tsh. | DE1: Vigen | DI1: Edmon | DM1: Minas
I2: score | L2: pts | M2: score | P2: pts | Q2: score | T2: pts | U2: score | X2: pts | Y2: score | AB2: pts | AC2: score | AF2: pts | AG2: score | AJ2: pts | AK2: score | AN2: pts | AO2: score | AR2: pts | AS2: score | AV2: pts | AW2: score | AZ2: pts | BA2: score | BD2: pts | BE2: score | BH2: pts | BI2: score | BL2: pts | BM2: score | BP2: pts | BQ2: score | BT2: pts | BU2: score | BX2: pts | BY2: score | CB2: pts | CC2: score | CF2: pts | CG2: score | CJ2: pts | CK2: score | CN2: pts | CO2: score | CR2: pts | CS2: score | CV2: pts | CW2: score | CZ2: pts | DA2: score | DD2: pts | DE2: score | DH2: pts | DI2: score | DL2: pts | DM2: score | DP2: pts
A3: Total points | I3: =SUM(L4:L75) -> 0 | M3: =SUM(P4:P75) -> 0 | Q3: =SUM(T4:T75) -> 0 | U3: =SUM(X4:X75) -> 0 | Y3: =SUM(AB4:AB75) -> 0 | AC3: =SUM(AF4:AF75) -> 0 | AG3: =SUM(AJ4:AJ75) -> 0 | AK3: =SUM(AN4:AN75) -> 0 | AO3: =SUM(AR4:AR75) -> 0 | AS3: =SUM(AV4:AV75) -> 0 | AW3: =SUM(AZ4:AZ75) -> 0 | BA3: =SUM(BD4:BD75) -> 0 | BE3: =SUM(BH4:BH75) -> 0 | BI3: =SUM(BL4:BL75) -> 0 | BM3: =SUM(BP4:BP75) -> 0 | BQ3: =SUM(BT4:BT75) -> 0 | BU3: =SUM(BX4:BX75) -> 0 | BY3: =SUM(CB4:CB75) -> 0 | CC3: =SUM(CF4:CF75) -> 0 | CG3: =SUM(CJ4:CJ75) -> 0 | CK3: =SUM(CN4:CN75) -> 0 | CO3: =SUM(CR4:CR75) -> 0 | CS3: =SUM(CV4:CV75) -> 0 | CW3: =SUM(CZ4:CZ75) -> 0 | DA3: =SUM(DD4:DD75) -> 0 | DE3: =SUM(DH4:DH75) -> 0 | DI3: =SUM(DL4:DL75) -> 0 | DM3: =SUM(DP4:DP75) -> 0
A4: 44722 | B4: 23:00 | C4: Mexico | D4: South Africa | E4: =L4+P4+T4+X4+AB4+AF4+AJ4+AN4+AR4+AV4+AZ4+BD4+BH4+BL4+BP4+BT4+BX4+CB4+CF4+CJ4+CN4+CR4+CV4+CZ4+DD4+DH4+DL4 -> 0 | H4: =IF(ISNUMBER(F4),IF(F4>G4,"1",IF(F4<G4,"2","X"))) -> FALSE | I4: 2 | J4: 0 | K4: =IF(I4>J4,"1",IF(I4<J4,"2","X")) -> 1 | L4: =IF(K4=$H4,IF(I4=$F4,IF(J4=$G4,IF($F4-$G4>=3,6,IF($G4-$F4>=3,6,IF($F4+$G4>=4,6,5))),3),3),0) -> 0 | M4: 3 | N4: 0 | O4: =IF(M4>N4,"1",IF(M4<N4,"2","X")) -> 1 | P4: =IF(O4=$H4,IF(M4=$F4,IF(N4=$G4,IF($F4-$G4>=3,6,IF($G4-$F4>=3,6,IF($F4+$G4>=4,6,5))),3),3),0) -> 0 | Q4: 3 | R4: 0 | S4: =IF(Q4>R4,"1",IF(Q4<R4,"2","X")) -> 1 | T4: =IF(S4=$H4,IF(Q4=$F4,IF(R4=$G4,IF($F4-$G4>=3,6,IF($G4-$F4>=3,6,IF($F4+$G4>=4,6,5))),3),3),0) -> 0 | U4: 1 | V4: 0 | W4: =IF(U4>V4,"1",IF(U4<V4,"2","X")) -> 1 | X4: =IF(W4=$H4,IF(U4=$F4,IF(V4=$G4,IF($F4-$G4>=3,6,IF($G4-$F4>=3,6,IF($F4+$G4>=4,6,5))),3),3),0) -> 0 | Y4: 3 | Z4: 0 | AA4: =IF(Y4>Z4,"1",IF(Y4<Z4,"2","X")) -> 1 | AB4: =IF(AA4=$H4,IF(Y4=$F4,IF(Z4=$G4,IF($F4-$G4>=3,6,IF($G4-$F4>=3,6,IF($F4+$G4>=4,6,5))),3),3),0) -> 0 | AC4: 2 | AD4: 0 | AE4: =IF(AC4>AD4,"1",IF(AC4<AD4,"2","X")) -> 1 | AF4: =IF(AE4=$H4,IF(AC4=$F4,IF(AD4=$G4,IF($F4-$G4>=3,6,IF($G4-$F4>=3,6,IF($F4+$G4>=4,6,5))),3),3),0) -> 0 | AG4: 2 | AH4: 1 | AI4: =IF(AG4>AH4,"1",IF(AG4<AH4,"2","X")) -> 1 | AJ4: =IF(AI4=$H4,IF(AG4=$F4,IF(AH4=$G4,IF($F4-$G4>=3,6,IF($G4-$F4>=3,6,IF($F4+$G4>=4,6,5))),3),3),0) -> 0 | AK4: 3 | AL4: 0 | AM4: =IF(AK4>AL4,"1",IF(AK4<AL4,"2","X")) -> 1 | AN4: =IF(AM4=$H4,IF(AK4=$F4,IF(AL4=$G4,IF($F4-$G4>=3,6,IF($G4-$F4>=3,6,IF($F4+$G4>=4,6,5))),3),3),0) -> 0 | AO4: 1 | AP4: 0 | AQ4: =IF(AO4>AP4,"1",IF(AO4<AP4,"2","X")) -> 1 | AR4: =IF(AQ4=$H4,IF(AO4=$F4,IF(AP4=$G4,IF($F4-$G4>=3,6,IF($G4-$F4>=3,6,IF($F4+$G4>=4,6,5))),3),3),0) -> 0 | AS4: 2 | AT4: 0 | AU4: =IF(AS4>AT4,"1",IF(AS4<AT4,"2","X")) -> 1 | AV4: =IF(AU4=$H4,IF(AS4=$F4,IF(AT4=$G4,IF($F4-$G4>=3,6,IF($G4-$F4>=3,6,IF($F4+$G4>=4,6,5))),3),3),0) -> 0 | AW4: 2 | AX4: 1 | AY4: =IF(AW4>AX4,"1",IF(AW4<AX4,"2","X")) -> 1 | AZ4: =IF(AY4=$H4,IF(AW4=$F4,IF(AX4=$G4,IF($F4-$G4>=3,6,IF($G4-$F4>=3,6,IF($F4+$G4>=4,6,5))),3),3),0) -> 0 | BA4: 2 | BB4: 0 | BC4: =IF(BA4>BB4,"1",IF(BA4<BB4,"2","X")) -> 1 | BD4: =IF(BC4=$H4,IF(BA4=$F4,IF(BB4=$G4,IF($F4-$G4>=3,6,IF($G4-$F4>=3,6,IF($F4+$G4>=4,6,5))),3),3),0) -> 0 | BE4: 1 | BF4: 0 | BG4: =IF(BE4>BF4,"1",IF(BE4<BF4,"2","X")) -> 1 | BH4: =IF(BG4=$H4,IF(BE4=$F4,IF(BF4=$G4,IF($F4-$G4>=3,6,IF($G4-$F4>=3,6,IF($F4+$G4>=4,6,5))),3),3),0) -> 0 | BI4: 1 | BJ4: 0 | BK4: =IF(BI4>BJ4,"1",IF(BI4<BJ4,"2","X")) -> 1 | BL4: =IF(BK4=$H4,IF(BI4=$F4,IF(BJ4=$G4,IF($F4-$G4>=3,6,IF($G4-$F4>=3,6,IF($F4+$G4>=4,6,5))),3),3),0) -> 0 | BM4: 1 | BN4: 0 | BO4: =IF(BM4>BN4,"1",IF(BM4<BN4,"2","X")) -> 1 | BP4: =IF(BO4=$H4,IF(BM4=$F4,IF(BN4=$G4,IF($F4-$G4>=3,6,IF($G4-$F4>=3,6,IF($F4+$G4>=4,6,5))),3),3),0) -> 0 | BQ4: 2 | BR4: 1 | BS4: =IF(BQ4>BR4,"1",IF(BQ4<BR4,"2","X")) -> 1 | BT4: =IF(BS4=$H4,IF(BQ4=$F4,IF(BR4=$G4,IF($F4-$G4>=3,6,IF($G4-$F4>=3,6,IF($F4+$G4>=4,6,5))),3),3),0) -> 0 | BU4: 2 | BV4: 1 | BW4: =IF(BU4>BV4,"1",IF(BU4<BV4,"2","X")) -> 1 | BX4: =IF(BW4=$H4,IF(BU4=$F4,IF(BV4=$G4,IF($F4-$G4>=3,6,IF($G4-$F4>=3,6,IF($F4+$G4>=4,6,5))),3),3),0) -> 0 | BY4: 2 | BZ4: 1 | CA4: =IF(BY4>BZ4,"1",IF(BY4<BZ4,"2","X")) -> 1 | CB4: =IF(CA4=$H4,IF(BY4=$F4,IF(BZ4=$G4,IF($F4-$G4>=3,6,IF($G4-$F4>=3,6,IF($F4+$G4>=4,6,5))),3),3),0) -> 0 | CC4: 2 | CD4: 1 | CE4: =IF(CC4>CD4,"1",IF(CC4<CD4,"2","X")) -> 1 | CF4: =IF(CE4=$H4,IF(CC4=$F4,IF(CD4=$G4,IF($F4-$G4>=3,6,IF($G4-$F4>=3,6,IF($F4+$G4>=4,6,5))),3),3),0) -> 0 | CG4: 2 | CH4: 0 | CI4: =IF(CG4>CH4,"1",IF(CG4<CH4,"2","X")) -> 1 | CJ4: =IF(CI4=$H4,IF(CG4=$F4,IF(CH4=$G4,IF($F4-$G4>=3,6,IF($G4-$F4>=3,6,IF($F4+$G4>=4,6,5))),3),3),0) -> 0 | CK4: 2 | CL4: 1 | CM4: =IF(CK4>CL4,"1",IF(CK4<CL4,"2","X")) -> 1 | CN4: =IF(CM4=$H4,IF(CK4=$F4,IF(CL4=$G4,IF($F4-$G4>=3,6,IF($G4-$F4>=3,6,IF($F4+$G4>=4,6,5))),3),3),0) -> 0 | CO4: 2 | CP4: 0 | CQ4: =IF(CO4>CP4,"1",IF(CO4<CP4,"2","X")) -> 1 | CR4: =IF(CQ4=$H4,IF(CO4=$F4,IF(CP4=$G4,IF($F4-$G4>=3,6,IF($G4-$F4>=3,6,IF($F4+$G4>=4,6,5))),3),3),0) -> 0 | CS4: 2 | CT4: 0 | CU4: =IF(CS4>CT4,"1",IF(CS4<CT4,"2","X")) -> 1 | CV4: =IF(CU4=$H4,IF(CS4=$F4,IF(CT4=$G4,IF($F4-$G4>=3,6,IF($G4-$F4>=3,6,IF($F4+$G4>=4,6,5))),3),3),0) -> 0 | CW4: 2 | CX4: 1 | CY4: =IF(CW4>CX4,"1",IF(CW4<CX4,"2","X")) -> 1 | CZ4: =IF(CY4=$H4,IF(CW4=$F4,IF(CX4=$G4,IF($F4-$G4>=3,6,IF($G4-$F4>=3,6,IF($F4+$G4>=4,6,5))),3),3),0) -> 0 | DA4: 2 | DB4: 0 | DC4: =IF(DA4>DB4,"1",IF(DA4<DB4,"2","X")) -> 1 | DD4: =IF(DC4=$H4,IF(DA4=$F4,IF(DB4=$G4,IF($F4-$G4>=3,6,IF($G4-$F4>=3,6,IF($F4+$G4>=4,6,5))),3),3),0) -> 0 | DE4: 2 | DF4: 0 | DG4: =IF(DE4>DF4,"1",IF(DE4<DF4,"2","X")) -> 1 | DH4: =IF(DG4=$H4,IF(DE4=$F4,IF(DF4=$G4,IF($F4-$G4>=3,6,IF($G4-$F4>=3,6,IF($F4+$G4>=4,6,5))),3),3),0) -> 0 | DI4: 2 | DJ4: 0 | DK4: =IF(DI4>DJ4,"1",IF(DI4<DJ4,"2","X")) -> 1 | DL4: =IF(DK4=$H4,IF(DI4=$F4,IF(DJ4=$G4,IF($F4-$G4>=3,6,IF($G4-$F4>=3,6,IF($F4+$G4>=4,6,5))),3),3),0) -> 0 | DM4: 2 | DN4: 0 | DO4: =IF(DM4>DN4,"1",IF(DM4<DN4,"2","X")) -> 1 | DP4: =IF(DO4=$H4,IF(DM4=$F4,IF(DN4=$G4,IF($F4-$G4>=3,6,IF($G4-$F4>=3,6,IF($F4+$G4>=4,6,5))),3),3),0) -> 0
A5: 44723 | B5: 06:00 | C5: South Korea | D5: Czech Republic | E5: =L5+P5+T5+X5+AB5+AF5+AJ5+AN5+AR5+AV5+AZ5+BD5+BH5+BL5+BP5+BT5+BX5+CB5+CF5+CJ5+CN5+CR5+CV5+CZ5+DD5+DH5+DL5 -> 0 | H5: =IF(ISNUMBER(F5),IF(F5>G5,"1",IF(F5<G5,"2","X"))) -> FALSE | I5: 1 | J5: 1 | K5: =IF(I5>J5,"1",IF(I5<J5,"2","X")) -> X | L5: =IF(K5=$H5,IF(I5=$F5,IF(J5=$G5,IF($F5-$G5>=3,6,IF($G5-$F5>=3,6,IF($F5+$G5>=4,6,5))),3),3),0) -> 0 | M5: 1 | N5: 1 | O5: =IF(M5>N5,"1",IF(M5<N5,"2","X")) -> X | P5: =IF(O5=$H5,IF(M5=$F5,IF(N5=$G5,IF($F5-$G5>=3,6,IF($G5-$F5>=3,6,IF($F5+$G5>=4,6,5))),3),3),0) -> 0 | Q5: 0 | R5: 0 | S5: =IF(Q5>R5,"1",IF(Q5<R5,"2","X")) -> X | T5: =IF(S5=$H5,IF(Q5=$F5,IF(R5=$G5,IF($F5-$G5>=3,6,IF($G5-$F5>=3,6,IF($F5+$G5>=4,6,5))),3),3),0) -> 0 | U5: 1 | V5: 1 | W5: =IF(U5>V5,"1",IF(U5<V5,"2","X")) -> X | X5: =IF(W5=$H5,IF(U5=$F5,IF(V5=$G5,IF($F5-$G5>=3,6,IF($G5-$F5>=3,6,IF($F5+$G5>=4,6,5))),3),3),0) -> 0 | Y5: 0 | Z5: 1 | AA5: =IF(Y5>Z5,"1",IF(Y5<Z5,"2","X")) -> 2 | AB5: =IF(AA5=$H5,IF(Y5=$F5,IF(Z5=$G5,IF($F5-$G5>=3,6,IF($G5-$F5>=3,6,IF($F5+$G5>=4,6,5))),3),3),0) -> 0 | AC5: 1 | AD5: 1 | AE5: =IF(AC5>AD5,"1",IF(AC5<AD5,"2","X")) -> X | AF5: =IF(AE5=$H5,IF(AC5=$F5,IF(AD5=$G5,IF($F5-$G5>=3,6,IF($G5-$F5>=3,6,IF($F5+$G5>=4,6,5))),3),3),0) -> 0 | AG5: 1 | AH5: 2 | AI5: =IF(AG5>AH5,"1",IF(AG5<AH5,"2","X")) -> 2 | AJ5: =IF(AI5=$H5,IF(AG5=$F5,IF(AH5=$G5,IF($F5-$G5>=3,6,IF($G5-$F5>=3,6,IF($F5+$G5>=4,6,5))),3),3),0) -> 0 | AK5: 0 | AL5: 2 | AM5: =IF(AK5>AL5,"1",IF(AK5<AL5,"2","X")) -> 2 | AN5: =IF(AM5=$H5,IF(AK5=$F5,IF(AL5=$G5,IF($F5-$G5>=3,6,IF($G5-$F5>=3,6,IF($F5+$G5>=4,6,5))),3),3),0) -> 0 | AO5: 2 | AP5: 1 | AQ5: =IF(AO5>AP5,"1",IF(AO5<AP5,"2","X")) -> 1 | AR5: =IF(AQ5=$H5,IF(AO5=$F5,IF(AP5=$G5,IF($F5-$G5>=3,6,IF($G5-$F5>=3,6,IF($F5+$G5>=4,6,5))),3),3),0) -> 0 | AS5: 2 | AT5: 1 | AU5: =IF(AS5>AT5,"1",IF(AS5<AT5,"2","X")) -> 1 | AV5: =IF(AU5=$H5,IF(AS5=$F5,IF(AT5=$G5,IF($F5-$G5>=3,6,IF($G5-$F5>=3,6,IF($F5+$G5>=4,6,5))),3),3),0) -> 0 | AW5: 1 | AX5: 1 | AY5: =IF(AW5>AX5,"1",IF(AW5<AX5,"2","X")) -> X | AZ5: =IF(AY5=$H5,IF(AW5=$F5,IF(AX5=$G5,IF($F5-$G5>=3,6,IF($G5-$F5>=3,6,IF($F5+$G5>=4,6,5))),3),3),0) -> 0 | BA5: 1 | BB5: 2 | BC5: =IF(BA5>BB5,"1",IF(BA5<BB5,"2","X")) -> 2 | BD5: =IF(BC5=$H5,IF(BA5=$F5,IF(BB5=$G5,IF($F5-$G5>=3,6,IF($G5-$F5>=3,6,IF($F5+$G5>=4,6,5))),3),3),0) -> 0 | BE5: 1 | BF5: 1 | BG5: =IF(BE5>BF5,"1",IF(BE5<BF5,"2","X")) -> X | BH5: =IF(BG5=$H5,IF(BE5=$F5,IF(BF5=$G5,IF($F5-$G5>=3,6,IF($G5-$F5>=3,6,IF($F5+$G5>=4,6,5))),3),3),0) -> 0 | BI5: 1 | BJ5: 0 | BK5: =IF(BI5>BJ5,"1",IF(BI5<BJ5,"2","X")) -> 1 | BL5: =IF(BK5=$H5,IF(BI5=$F5,IF(BJ5=$G5,IF($F5-$G5>=3,6,IF($G5-$F5>=3,6,IF($F5+$G5>=4,6,5))),3),3),0) -> 0 | BM5: 0 | BN5: 1 | BO5: =IF(BM5>BN5,"1",IF(BM5<BN5,"2","X")) -> 2 | BP5: =IF(BO5=$H5,IF(BM5=$F5,IF(BN5=$G5,IF($F5-$G5>=3,6,IF($G5-$F5>=3,6,IF($F5+$G5>=4,6,5))),3),3),0) -> 0 | BQ5: 1 | BR5: 2 | BS5: =IF(BQ5>BR5,"1",IF(BQ5<BR5,"2","X")) -> 2 | BT5: =IF(BS5=$H5,IF(BQ5=$F5,IF(BR5=$G5,IF($F5-$G5>=3,6,IF($G5-$F5>=3,6,IF($F5+$G5>=4,6,5))),3),3),0) -> 0 | BU5: 2 | BV5: 3 | BW5: =IF(BU5>BV5,"1",IF(BU5<BV5,"2","X")) -> 2 | BX5: =IF(BW5=$H5,IF(BU5=$F5,IF(BV5=$G5,IF($F5-$G5>=3,6,IF($G5-$F5>=3,6,IF($F5+$G5>=4,6,5))),3),3),0) -> 0 | BY5: 1 | BZ5: 1 | CA5: =IF(BY5>BZ5,"1",IF(BY5<BZ5,"2","X")) -> X | CB5: =IF(CA5=$H5,IF(BY5=$F5,IF(BZ5=$G5,IF($F5-$G5>=3,6,IF($G5-$F5>=3,6,IF($F5+$G5>=4,6,5))),3),3),0) -> 0 | CC5: 1 | CD5: 1 | CE5: =IF(CC5>CD5,"1",IF(CC5<CD5,"2","X")) -> X | CF5: =IF(CE5=$H5,IF(CC5=$F5,IF(CD5=$G5,IF($F5-$G5>=3,6,IF($G5-$F5>=3,6,IF($F5+$G5>=4,6,5))),3),3),0) -> 0 | CG5: 1 | CH5: 1 | CI5: =IF(CG5>CH5,"1",IF(CG5<CH5,"2","X")) -> X | CJ5: =IF(CI5=$H5,IF(CG5=$F5,IF(CH5=$G5,IF($F5-$G5>=3,6,IF($G5-$F5>=3,6,IF($F5+$G5>=4,6,5))),3),3),0) -> 0 | CK5: 1 | CL5: 2 | CM5: =IF(CK5>CL5,"1",IF(CK5<CL5,"2","X")) -> 2 | CN5: =IF(CM5=$H5,IF(CK5=$F5,IF(CL5=$G5,IF($F5-$G5>=3,6,IF($G5-$F5>=3,6,IF($F5+$G5>=4,6,5))),3),3),0) -> 0 | CO5: 1 | CP5: 0 | CQ5: =IF(CO5>CP5,"1",IF(CO5<CP5,"2","X")) -> 1 | CR5: =IF(CQ5=$H5,IF(CO5=$F5,IF(CP5=$G5,IF($F5-$G5>=3,6,IF($G5-$F5>=3,6,IF($F5+$G5>=4,6,5))),3),3),0) -> 0 | CS5: 1 | CT5: 1 | CU5: =IF(CS5>CT5,"1",IF(CS5<CT5,"2","X")) -> X | CV5: =IF(CU5=$H5,IF(CS5=$F5,IF(CT5=$G5,IF($F5-$G5>=3,6,IF($G5-$F5>=3,6,IF($F5+$G5>=4,6,5))),3),3),0) -> 0 | CW5: 1 | CX5: 2 | CY5: =IF(CW5>CX5,"1",IF(CW5<CX5,"2","X")) -> 2 | CZ5: =IF(CY5=$H5,IF(CW5=$F5,IF(CX5=$G5,IF($F5-$G5>=3,6,IF($G5-$F5>=3,6,IF($F5+$G5>=4,6,5))),3),3),0) -> 0 | DA5: 0 | DB5: 1 | DC5: =IF(DA5>DB5,"1",IF(DA5<DB5,"2","X")) -> 2 | DD5: =IF(DC5=$H5,IF(DA5=$F5,IF(DB5=$G5,IF($F5-$G5>=3,6,IF($G5-$F5>=3,6,IF($F5+$G5>=4,6,5))),3),3),0) -> 0 | DE5: 1 | DF5: 1 | DG5: =IF(DE5>DF5,"1",IF(DE5<DF5,"2","X")) -> X | DH5: =IF(DG5=$H5,IF(DE5=$F5,IF(DF5=$G5,IF($F5-$G5>=3,6,IF($G5-$F5>=3,6,IF($F5+$G5>=4,6,5))),3),3),0) -> 0 | DI5: 1 | DJ5: 2 | DK5: =IF(DI5>DJ5,"1",IF(DI5<DJ5,"2","X")) -> 2 | DL5: =IF(DK5=$H5,IF(DI5=$F5,IF(DJ5=$G5,IF($F5-$G5>=3,6,IF($G5-$F5>=3,6,IF($F5+$G5>=4,6,5))),3),3),0) -> 0 | DM5: 1 | DN5: 1 | DO5: =IF(DM5>DN5,"1",IF(DM5<DN5,"2","X")) -> X | DP5: =IF(DO5=$H5,IF(DM5=$F5,IF(DN5=$G5,IF($F5-$G5>=3,6,IF($G5-$F5>=3,6,IF($F5+$G5>=4,6,5))),3),3),0) -> 0
A6: 44729 | B6: 20:00 | C6: Czech Republic | D6: South Africa | E6: =L6+P6+T6+X6+AB6+AF6+AJ6+AN6+AR6+AV6+AZ6+BD6+BH6+BL6+BP6+BT6+BX6+CB6+CF6+CJ6+CN6+CR6+CV6+CZ6+DD6+DH6+DL6 -> 0 | H6: =IF(ISNUMBER(F6),IF(F6>G6,"1",IF(F6<G6,"2","X"))) -> FALSE | I6: 2 | J6: 0 | K6: =IF(I6>J6,"1",IF(I6<J6,"2","X")) -> 1 | L6: =IF(K6=$H6,IF(I6=$F6,IF(J6=$G6,IF($F6-$G6>=3,6,IF($G6-$F6>=3,6,IF($F6+$G6>=4,6,5))),3),3),0) -> 0 | M6: 2 | N6: 1 | O6: =IF(M6>N6,"1",IF(M6<N6,"2","X")) -> 1 | P6: =IF(O6=$H6,IF(M6=$F6,IF(N6=$G6,IF($F6-$G6>=3,6,IF($G6-$F6>=3,6,IF($F6+$G6>=4,6,5))),3),3),0) -> 0 | Q6: 2 | R6: 1 | S6: =IF(Q6>R6,"1",IF(Q6<R6,"2","X")) -> 1 | T6: =IF(S6=$H6,IF(Q6=$F6,IF(R6=$G6,IF($F6-$G6>=3,6,IF($G6-$F6>=3,6,IF($F6+$G6>=4,6,5))),3),3),0) -> 0 | U6: 2 | V6: 0 | W6: =IF(U6>V6,"1",IF(U6<V6,"2","X")) -> 1 | X6: =IF(W6=$H6,IF(U6=$F6,IF(V6=$G6,IF($F6-$G6>=3,6,IF($G6-$F6>=3,6,IF($F6+$G6>=4,6,5))),3),3),0) -> 0 | Y6: 2 | Z6: 1 | AA6: =IF(Y6>Z6,"1",IF(Y6<Z6,"2","X")) -> 1 | AB6: =IF(AA6=$H6,IF(Y6=$F6,IF(Z6=$G6,IF($F6-$G6>=3,6,IF($G6-$F6>=3,6,IF($F6+$G6>=4,6,5))),3),3),0) -> 0 | AC6: 2 | AD6: 0 | AE6: =IF(AC6>AD6,"1",IF(AC6<AD6,"2","X")) -> 1 | AF6: =IF(AE6=$H6,IF(AC6=$F6,IF(AD6=$G6,IF($F6-$G6>=3,6,IF($G6-$F6>=3,6,IF($F6+$G6>=4,6,5))),3),3),0) -> 0 | AG6: 1 | AH6: 1 | AI6: =IF(AG6>AH6,"1",IF(AG6<AH6,"2","X")) -> X | AJ6: =IF(AI6=$H6,IF(AG6=$F6,IF(AH6=$G6,IF($F6-$G6>=3,6,IF($G6-$F6>=3,6,IF($F6+$G6>=4,6,5))),3),3),0) -> 0 | AK6: 2 | AL6: 1 | AM6: =IF(AK6>AL6,"1",IF(AK6<AL6,"2","X")) -> 1 | AN6: =IF(AM6=$H6,IF(AK6=$F6,IF(AL6=$G6,IF($F6-$G6>=3,6,IF($G6-$F6>=3,6,IF($F6+$G6>=4,6,5))),3),3),0) -> 0 | AO6: 0 | AP6: 0 | AQ6: =IF(AO6>AP6,"1",IF(AO6<AP6,"2","X")) -> X | AR6: =IF(AQ6=$H6,IF(AO6=$F6,IF(AP6=$G6,IF($F6-$G6>=3,6,IF($G6-$F6>=3,6,IF($F6+$G6>=4,6,5))),3),3),0) -> 0 | AS6: 2 | AT6: 0 | AU6: =IF(AS6>AT6,"1",IF(AS6<AT6,"2","X")) -> 1 | AV6: =IF(AU6=$H6,IF(AS6=$F6,IF(AT6=$G6,IF($F6-$G6>=3,6,IF($G6-$F6>=3,6,IF($F6+$G6>=4,6,5))),3),3),0) -> 0 | AW6: 0 | AX6: 0 | AY6: =IF(AW6>AX6,"1",IF(AW6<AX6,"2","X")) -> X | AZ6: =IF(AY6=$H6,IF(AW6=$F6,IF(AX6=$G6,IF($F6-$G6>=3,6,IF($G6-$F6>=3,6,IF($F6+$G6>=4,6,5))),3),3),0) -> 0 | BA6: 1 | BB6: 0 | BC6: =IF(BA6>BB6,"1",IF(BA6<BB6,"2","X")) -> 1 | BD6: =IF(BC6=$H6,IF(BA6=$F6,IF(BB6=$G6,IF($F6-$G6>=3,6,IF($G6-$F6>=3,6,IF($F6+$G6>=4,6,5))),3),3),0) -> 0 | BE6: 2 | BF6: 1 | BG6: =IF(BE6>BF6,"1",IF(BE6<BF6,"2","X")) -> 1 | BH6: =IF(BG6=$H6,IF(BE6=$F6,IF(BF6=$G6,IF($F6-$G6>=3,6,IF($G6-$F6>=3,6,IF($F6+$G6>=4,6,5))),3),3),0) -> 0 | BI6: 2 | BJ6: 1 | BK6: =IF(BI6>BJ6,"1",IF(BI6<BJ6,"2","X")) -> 1 | BL6: =IF(BK6=$H6,IF(BI6=$F6,IF(BJ6=$G6,IF($F6-$G6>=3,6,IF($G6-$F6>=3,6,IF($F6+$G6>=4,6,5))),3),3),0) -> 0 | BM6: 2 | BN6: 0 | BO6: =IF(BM6>BN6,"1",IF(BM6<BN6,"2","X")) -> 1 | BP6: =IF(BO6=$H6,IF(BM6=$F6,IF(BN6=$G6,IF($F6-$G6>=3,6,IF($G6-$F6>=3,6,IF($F6+$G6>=4,6,5))),3),3),0) -> 0 | BQ6: 2 | BR6: 0 | BS6: =IF(BQ6>BR6,"1",IF(BQ6<BR6,"2","X")) -> 1 | BT6: =IF(BS6=$H6,IF(BQ6=$F6,IF(BR6=$G6,IF($F6-$G6>=3,6,IF($G6-$F6>=3,6,IF($F6+$G6>=4,6,5))),3),3),0) -> 0 | BU6: 1 | BV6: 0 | BW6: =IF(BU6>BV6,"1",IF(BU6<BV6,"2","X")) -> 1 | BX6: =IF(BW6=$H6,IF(BU6=$F6,IF(BV6=$G6,IF($F6-$G6>=3,6,IF($G6-$F6>=3,6,IF($F6+$G6>=4,6,5))),3),3),0) -> 0 | BY6: 0 | BZ6: 2 | CA6: =IF(BY6>BZ6,"1",IF(BY6<BZ6,"2","X")) -> 2 | CB6: =IF(CA6=$H6,IF(BY6=$F6,IF(BZ6=$G6,IF($F6-$G6>=3,6,IF($G6-$F6>=3,6,IF($F6+$G6>=4,6,5))),3),3),0) -> 0 | CC6: 2 | CD6: 1 | CE6: =IF(CC6>CD6,"1",IF(CC6<CD6,"2","X")) -> 1 | CF6: =IF(CE6=$H6,IF(CC6=$F6,IF(CD6=$G6,IF($F6-$G6>=3,6,IF($G6-$F6>=3,6,IF($F6+$G6>=4,6,5))),3),3),0) -> 0 | CG6: 2 | CH6: 0 | CI6: =IF(CG6>CH6,"1",IF(CG6<CH6,"2","X")) -> 1 | CJ6: =IF(CI6=$H6,IF(CG6=$F6,IF(CH6=$G6,IF($F6-$G6>=3,6,IF($G6-$F6>=3,6,IF($F6+$G6>=4,6,5))),3),3),0) -> 0 | CK6: 3 | CL6: 1 | CM6: =IF(CK6>CL6,"1",IF(CK6<CL6,"2","X")) -> 1 | CN6: =IF(CM6=$H6,IF(CK6=$F6,IF(CL6=$G6,IF($F6-$G6>=3,6,IF($G6-$F6>=3,6,IF($F6+$G6>=4,6,5))),3),3),0) -> 0 | CO6: 1 | CP6: 0 | CQ6: =IF(CO6>CP6,"1",IF(CO6<CP6,"2","X")) -> 1 | CR6: =IF(CQ6=$H6,IF(CO6=$F6,IF(CP6=$G6,IF($F6-$G6>=3,6,IF($G6-$F6>=3,6,IF($F6+$G6>=4,6,5))),3),3),0) -> 0 | CS6: 1 | CT6: 0 | CU6: =IF(CS6>CT6,"1",IF(CS6<CT6,"2","X")) -> 1 | CV6: =IF(CU6=$H6,IF(CS6=$F6,IF(CT6=$G6,IF($F6-$G6>=3,6,IF($G6-$F6>=3,6,IF($F6+$G6>=4,6,5))),3),3),0) -> 0 | CW6: 1 | CX6: 2 | CY6: =IF(CW6>CX6,"1",IF(CW6<CX6,"2","X")) -> 2 | CZ6: =IF(CY6=$H6,IF(CW6=$F6,IF(CX6=$G6,IF($F6-$G6>=3,6,IF($G6-$F6>=3,6,IF($F6+$G6>=4,6,5))),3),3),0) -> 0 | DA6: 1 | DB6: 0 | DC6: =IF(DA6>DB6,"1",IF(DA6<DB6,"2","X")) -> 1 | DD6: =IF(DC6=$H6,IF(DA6=$F6,IF(DB6=$G6,IF($F6-$G6>=3,6,IF($G6-$F6>=3,6,IF($F6+$G6>=4,6,5))),3),3),0) -> 0 | DE6: 1 | DF6: 0 | DG6: =IF(DE6>DF6,"1",IF(DE6<DF6,"2","X")) -> 1 | DH6: =IF(DG6=$H6,IF(DE6=$F6,IF(DF6=$G6,IF($F6-$G6>=3,6,IF($G6-$F6>=3,6,IF($F6+$G6>=4,6,5))),3),3),0) -> 0 | DI6: 2 | DJ6: 0 | DK6: =IF(DI6>DJ6,"1",IF(DI6<DJ6,"2","X")) -> 1 | DL6: =IF(DK6=$H6,IF(DI6=$F6,IF(DJ6=$G6,IF($F6-$G6>=3,6,IF($G6-$F6>=3,6,IF($F6+$G6>=4,6,5))),3),3),0) -> 0 | DM6: 0 | DN6: 0 | DO6: =IF(DM6>DN6,"1",IF(DM6<DN6,"2","X")) -> X | DP6: =IF(DO6=$H6,IF(DM6=$F6,IF(DN6=$G6,IF($F6-$G6>=3,6,IF($G6-$F6>=3,6,IF($F6+$G6>=4,6,5))),3),3),0) -> 0
A7: 44730 | B7: 05:00 | C7: Mexico | D7: South Korea | E7: =L7+P7+T7+X7+AB7+AF7+AJ7+AN7+AR7+AV7+AZ7+BD7+BH7+BL7+BP7+BT7+BX7+CB7+CF7+CJ7+CN7+CR7+CV7+CZ7+DD7+DH7+DL7 -> 0 | H7: =IF(ISNUMBER(F7),IF(F7>G7,"1",IF(F7<G7,"2","X"))) -> FALSE | I7: 2 | J7: 1 | K7: =IF(I7>J7,"1",IF(I7<J7,"2","X")) -> 1 | L7: =IF(K7=$H7,IF(I7=$F7,IF(J7=$G7,IF($F7-$G7>=3,6,IF($G7-$F7>=3,6,IF($F7+$G7>=4,6,5))),3),3),0) -> 0 | M7: 1 | N7: 1 | O7: =IF(M7>N7,"1",IF(M7<N7,"2","X")) -> X | P7: =IF(O7=$H7,IF(M7=$F7,IF(N7=$G7,IF($F7-$G7>=3,6,IF($G7-$F7>=3,6,IF($F7+$G7>=4,6,5))),3),3),0) -> 0 | Q7: 2 | R7: 1 | S7: =IF(Q7>R7,"1",IF(Q7<R7,"2","X")) -> 1 | T7: =IF(S7=$H7,IF(Q7=$F7,IF(R7=$G7,IF($F7-$G7>=3,6,IF($G7-$F7>=3,6,IF($F7+$G7>=4,6,5))),3),3),0) -> 0 | U7: 2 | V7: 0 | W7: =IF(U7>V7,"1",IF(U7<V7,"2","X")) -> 1 | X7: =IF(W7=$H7,IF(U7=$F7,IF(V7=$G7,IF($F7-$G7>=3,6,IF($G7-$F7>=3,6,IF($F7+$G7>=4,6,5))),3),3),0) -> 0 | Y7: 1 | Z7: 1 | AA7: =IF(Y7>Z7,"1",IF(Y7<Z7,"2","X")) -> X | AB7: =IF(AA7=$H7,IF(Y7=$F7,IF(Z7=$G7,IF($F7-$G7>=3,6,IF($G7-$F7>=3,6,IF($F7+$G7>=4,6,5))),3),3),0) -> 0 | AC7: 2 | AD7: 1 | AE7: =IF(AC7>AD7,"1",IF(AC7<AD7,"2","X")) -> 1 | AF7: =IF(AE7=$H7,IF(AC7=$F7,IF(AD7=$G7,IF($F7-$G7>=3,6,IF($G7-$F7>=3,6,IF($F7+$G7>=4,6,5))),3),3),0) -> 0 | AG7: 1 | AH7: 1 | AI7: =IF(AG7>AH7,"1",IF(AG7<AH7,"2","X")) -> X | AJ7: =IF(AI7=$H7,IF(AG7=$F7,IF(AH7=$G7,IF($F7-$G7>=3,6,IF($G7-$F7>=3,6,IF($F7+$G7>=4,6,5))),3),3),0) -> 0 | AK7: 3 | AL7: 0 | AM7: =IF(AK7>AL7,"1",IF(AK7<AL7,"2","X")) -> 1 | AN7: =IF(AM7=$H7,IF(AK7=$F7,IF(AL7=$G7,IF($F7-$G7>=3,6,IF($G7-$F7>=3,6,IF($F7+$G7>=4,6,5))),3),3),0) -> 0 | AO7: 2 | AP7: 2 | AQ7: =IF(AO7>AP7,"1",IF(AO7<AP7,"2","X")) -> X | AR7: =IF(AQ7=$H7,IF(AO7=$F7,IF(AP7=$G7,IF($F7-$G7>=3,6,IF($G7-$F7>=3,6,IF($F7+$G7>=4,6,5))),3),3),0) -> 0 | AS7: 1 | AT7: 1 | AU7: =IF(AS7>AT7,"1",IF(AS7<AT7,"2","X")) -> X | AV7: =IF(AU7=$H7,IF(AS7=$F7,IF(AT7=$G7,IF($F7-$G7>=3,6,IF($G7-$F7>=3,6,IF($F7+$G7>=4,6,5))),3),3),0) -> 0 | AW7: 1 | AX7: 1 | AY7: =IF(AW7>AX7,"1",IF(AW7<AX7,"2","X")) -> X | AZ7: =IF(AY7=$H7,IF(AW7=$F7,IF(AX7=$G7,IF($F7-$G7>=3,6,IF($G7-$F7>=3,6,IF($F7+$G7>=4,6,5))),3),3),0) -> 0 | BA7: 3 | BB7: 1 | BC7: =IF(BA7>BB7,"1",IF(BA7<BB7,"2","X")) -> 1 | BD7: =IF(BC7=$H7,IF(BA7=$F7,IF(BB7=$G7,IF($F7-$G7>=3,6,IF($G7-$F7>=3,6,IF($F7+$G7>=4,6,5))),3),3),0) -> 0 | BE7: 1 | BF7: 2 | BG7: =IF(BE7>BF7,"1",IF(BE7<BF7,"2","X")) -> 2 | BH7: =IF(BG7=$H7,IF(BE7=$F7,IF(BF7=$G7,IF($F7-$G7>=3,6,IF($G7-$F7>=3,6,IF($F7+$G7>=4,6,5))),3),3),0) -> 0 | BI7: 1 | BJ7: 1 | BK7: =IF(BI7>BJ7,"1",IF(BI7<BJ7,"2","X")) -> X | BL7: =IF(BK7=$H7,IF(BI7=$F7,IF(BJ7=$G7,IF($F7-$G7>=3,6,IF($G7-$F7>=3,6,IF($F7+$G7>=4,6,5))),3),3),0) -> 0 | BM7: 2 | BN7: 1 | BO7: =IF(BM7>BN7,"1",IF(BM7<BN7,"2","X")) -> 1 | BP7: =IF(BO7=$H7,IF(BM7=$F7,IF(BN7=$G7,IF($F7-$G7>=3,6,IF($G7-$F7>=3,6,IF($F7+$G7>=4,6,5))),3),3),0) -> 0 | BQ7: 2 | BR7: 1 | BS7: =IF(BQ7>BR7,"1",IF(BQ7<BR7,"2","X")) -> 1 | BT7: =IF(BS7=$H7,IF(BQ7=$F7,IF(BR7=$G7,IF($F7-$G7>=3,6,IF($G7-$F7>=3,6,IF($F7+$G7>=4,6,5))),3),3),0) -> 0 | BU7: 2 | BV7: 0 | BW7: =IF(BU7>BV7,"1",IF(BU7<BV7,"2","X")) -> 1 | BX7: =IF(BW7=$H7,IF(BU7=$F7,IF(BV7=$G7,IF($F7-$G7>=3,6,IF($G7-$F7>=3,6,IF($F7+$G7>=4,6,5))),3),3),0) -> 0 | BY7: 1 | BZ7: 0 | CA7: =IF(BY7>BZ7,"1",IF(BY7<BZ7,"2","X")) -> 1 | CB7: =IF(CA7=$H7,IF(BY7=$F7,IF(BZ7=$G7,IF($F7-$G7>=3,6,IF($G7-$F7>=3,6,IF($F7+$G7>=4,6,5))),3),3),0) -> 0 | CC7: 2 | CD7: 0 | CE7: =IF(CC7>CD7,"1",IF(CC7<CD7,"2","X")) -> 1 | CF7: =IF(CE7=$H7,IF(CC7=$F7,IF(CD7=$G7,IF($F7-$G7>=3,6,IF($G7-$F7>=3,6,IF($F7+$G7>=4,6,5))),3),3),0) -> 0 | CG7: 1 | CH7: 0 | CI7: =IF(CG7>CH7,"1",IF(CG7<CH7,"2","X")) -> 1 | CJ7: =IF(CI7=$H7,IF(CG7=$F7,IF(CH7=$G7,IF($F7-$G7>=3,6,IF($G7-$F7>=3,6,IF($F7+$G7>=4,6,5))),3),3),0) -> 0 | CK7: 2 | CL7: 0 | CM7: =IF(CK7>CL7,"1",IF(CK7<CL7,"2","X")) -> 1 | CN7: =IF(CM7=$H7,IF(CK7=$F7,IF(CL7=$G7,IF($F7-$G7>=3,6,IF($G7-$F7>=3,6,IF($F7+$G7>=4,6,5))),3),3),0) -> 0 | CO7: 2 | CP7: 1 | CQ7: =IF(CO7>CP7,"1",IF(CO7<CP7,"2","X")) -> 1 | CR7: =IF(CQ7=$H7,IF(CO7=$F7,IF(CP7=$G7,IF($F7-$G7>=3,6,IF($G7-$F7>=3,6,IF($F7+$G7>=4,6,5))),3),3),0) -> 0 | CS7: 1 | CT7: 0 | CU7: =IF(CS7>CT7,"1",IF(CS7<CT7,"2","X")) -> 1 | CV7: =IF(CU7=$H7,IF(CS7=$F7,IF(CT7=$G7,IF($F7-$G7>=3,6,IF($G7-$F7>=3,6,IF($F7+$G7>=4,6,5))),3),3),0) -> 0 | CW7: 2 | CX7: 1 | CY7: =IF(CW7>CX7,"1",IF(CW7<CX7,"2","X")) -> 1 | CZ7: =IF(CY7=$H7,IF(CW7=$F7,IF(CX7=$G7,IF($F7-$G7>=3,6,IF($G7-$F7>=3,6,IF($F7+$G7>=4,6,5))),3),3),0) -> 0 | DA7: 2 | DB7: 1 | DC7: =IF(DA7>DB7,"1",IF(DA7<DB7,"2","X")) -> 1 | DD7: =IF(DC7=$H7,IF(DA7=$F7,IF(DB7=$G7,IF($F7-$G7>=3,6,IF($G7-$F7>=3,6,IF($F7+$G7>=4,6,5))),3),3),0) -> 0 | DE7: 2 | DF7: 1 | DG7: =IF(DE7>DF7,"1",IF(DE7<DF7,"2","X")) -> 1 | DH7: =IF(DG7=$H7,IF(DE7=$F7,IF(DF7=$G7,IF($F7-$G7>=3,6,IF($G7-$F7>=3,6,IF($F7+$G7>=4,6,5))),3),3),0) -> 0 | DI7: 2 | DJ7: 1 | DK7: =IF(DI7>DJ7,"1",IF(DI7<DJ7,"2","X")) -> 1 | DL7: =IF(DK7=$H7,IF(DI7=$F7,IF(DJ7=$G7,IF($F7-$G7>=3,6,IF($G7-$F7>=3,6,IF($F7+$G7>=4,6,5))),3),3),0) -> 0 | DM7: 2 | DN7: 2 | DO7: =IF(DM7>DN7,"1",IF(DM7<DN7,"2","X")) -> X | DP7: =IF(DO7=$H7,IF(DM7=$F7,IF(DN7=$G7,IF($F7-$G7>=3,6,IF($G7-$F7>=3,6,IF($F7+$G7>=4,6,5))),3),3),0) -> 0
A8: 44736 | B8: 05:00 | C8: Czech Republic | D8: Mexico | E8: =L8+P8+T8+X8+AB8+AF8+AJ8+AN8+AR8+AV8+AZ8+BD8+BH8+BL8+BP8+BT8+BX8+CB8+CF8+CJ8+CN8+CR8+CV8+CZ8+DD8+DH8+DL8 -> 0 | H8: =IF(ISNUMBER(F8),IF(F8>G8,"1",IF(F8<G8,"2","X"))) -> FALSE | K8: =IF(I8>J8,"1",IF(I8<J8,"2","X")) -> X | L8: =IF(K8=$H8,IF(I8=$F8,IF(J8=$G8,IF($F8-$G8>=3,6,IF($G8-$F8>=3,6,IF($F8+$G8>=4,6,5))),3),3),0) -> 0 | O8: =IF(M8>N8,"1",IF(M8<N8,"2","X")) -> X | P8: =IF(O8=$H8,IF(M8=$F8,IF(N8=$G8,IF($F8-$G8>=3,6,IF($G8-$F8>=3,6,IF($F8+$G8>=4,6,5))),3),3),0) -> 0 | S8: =IF(Q8>R8,"1",IF(Q8<R8,"2","X")) -> X | T8: =IF(S8=$H8,IF(Q8=$F8,IF(R8=$G8,IF($F8-$G8>=3,6,IF($G8-$F8>=3,6,IF($F8+$G8>=4,6,5))),3),3),0) -> 0 | W8: =IF(U8>V8,"1",IF(U8<V8,"2","X")) -> X | X8: =IF(W8=$H8,IF(U8=$F8,IF(V8=$G8,IF($F8-$G8>=3,6,IF($G8-$F8>=3,6,IF($F8+$G8>=4,6,5))),3),3),0) -> 0 | AA8: =IF(Y8>Z8,"1",IF(Y8<Z8,"2","X")) -> X | AB8: =IF(AA8=$H8,IF(Y8=$F8,IF(Z8=$G8,IF($F8-$G8>=3,6,IF($G8-$F8>=3,6,IF($F8+$G8>=4,6,5))),3),3),0) -> 0 | AE8: =IF(AC8>AD8,"1",IF(AC8<AD8,"2","X")) -> X | AF8: =IF(AE8=$H8,IF(AC8=$F8,IF(AD8=$G8,IF($F8-$G8>=3,6,IF($G8-$F8>=3,6,IF($F8+$G8>=4,6,5))),3),3),0) -> 0 | AI8: =IF(AG8>AH8,"1",IF(AG8<AH8,"2","X")) -> X | AJ8: =IF(AI8=$H8,IF(AG8=$F8,IF(AH8=$G8,IF($F8-$G8>=3,6,IF($G8-$F8>=3,6,IF($F8+$G8>=4,6,5))),3),3),0) -> 0 | AM8: =IF(AK8>AL8,"1",IF(AK8<AL8,"2","X")) -> X | AN8: =IF(AM8=$H8,IF(AK8=$F8,IF(AL8=$G8,IF($F8-$G8>=3,6,IF($G8-$F8>=3,6,IF($F8+$G8>=4,6,5))),3),3),0) -> 0 | AQ8: =IF(AO8>AP8,"1",IF(AO8<AP8,"2","X")) -> X | AR8: =IF(AQ8=$H8,IF(AO8=$F8,IF(AP8=$G8,IF($F8-$G8>=3,6,IF($G8-$F8>=3,6,IF($F8+$G8>=4,6,5))),3),3),0) -> 0 | AU8: =IF(AS8>AT8,"1",IF(AS8<AT8,"2","X")) -> X | AV8: =IF(AU8=$H8,IF(AS8=$F8,IF(AT8=$G8,IF($F8-$G8>=3,6,IF($G8-$F8>=3,6,IF($F8+$G8>=4,6,5))),3),3),0) -> 0 | AY8: =IF(AW8>AX8,"1",IF(AW8<AX8,"2","X")) -> X | AZ8: =IF(AY8=$H8,IF(AW8=$F8,IF(AX8=$G8,IF($F8-$G8>=3,6,IF($G8-$F8>=3,6,IF($F8+$G8>=4,6,5))),3),3),0) -> 0 | BC8: =IF(BA8>BB8,"1",IF(BA8<BB8,"2","X")) -> X | BD8: =IF(BC8=$H8,IF(BA8=$F8,IF(BB8=$G8,IF($F8-$G8>=3,6,IF($G8-$F8>=3,6,IF($F8+$G8>=4,6,5))),3),3),0) -> 0 | BG8: =IF(BE8>BF8,"1",IF(BE8<BF8,"2","X")) -> X | BH8: =IF(BG8=$H8,IF(BE8=$F8,IF(BF8=$G8,IF($F8-$G8>=3,6,IF($G8-$F8>=3,6,IF($F8+$G8>=4,6,5))),3),3),0) -> 0 | BK8: =IF(BI8>BJ8,"1",IF(BI8<BJ8,"2","X")) -> X | BL8: =IF(BK8=$H8,IF(BI8=$F8,IF(BJ8=$G8,IF($F8-$G8>=3,6,IF($G8-$F8>=3,6,IF($F8+$G8>=4,6,5))),3),3),0) -> 0 | BO8: =IF(BM8>BN8,"1",IF(BM8<BN8,"2","X")) -> X | BP8: =IF(BO8=$H8,IF(BM8=$F8,IF(BN8=$G8,IF($F8-$G8>=3,6,IF($G8-$F8>=3,6,IF($F8+$G8>=4,6,5))),3),3),0) -> 0 | BS8: =IF(BQ8>BR8,"1",IF(BQ8<BR8,"2","X")) -> X | BT8: =IF(BS8=$H8,IF(BQ8=$F8,IF(BR8=$G8,IF($F8-$G8>=3,6,IF($G8-$F8>=3,6,IF($F8+$G8>=4,6,5))),3),3),0) -> 0 | BW8: =IF(BU8>BV8,"1",IF(BU8<BV8,"2","X")) -> X | BX8: =IF(BW8=$H8,IF(BU8=$F8,IF(BV8=$G8,IF($F8-$G8>=3,6,IF($G8-$F8>=3,6,IF($F8+$G8>=4,6,5))),3),3),0) -> 0 | CA8: =IF(BY8>BZ8,"1",IF(BY8<BZ8,"2","X")) -> X | CB8: =IF(CA8=$H8,IF(BY8=$F8,IF(BZ8=$G8,IF($F8-$G8>=3,6,IF($G8-$F8>=3,6,IF($F8+$G8>=4,6,5))),3),3),0) -> 0 | CE8: =IF(CC8>CD8,"1",IF(CC8<CD8,"2","X")) -> X | CF8: =IF(CE8=$H8,IF(CC8=$F8,IF(CD8=$G8,IF($F8-$G8>=3,6,IF($G8-$F8>=3,6,IF($F8+$G8>=4,6,5))),3),3),0) -> 0 | CI8: =IF(CG8>CH8,"1",IF(CG8<CH8,"2","X")) -> X | CJ8: =IF(CI8=$H8,IF(CG8=$F8,IF(CH8=$G8,IF($F8-$G8>=3,6,IF($G8-$F8>=3,6,IF($F8+$G8>=4,6,5))),3),3),0) -> 0 | CM8: =IF(CK8>CL8,"1",IF(CK8<CL8,"2","X")) -> X | CN8: =IF(CM8=$H8,IF(CK8=$F8,IF(CL8=$G8,IF($F8-$G8>=3,6,IF($G8-$F8>=3,6,IF($F8+$G8>=4,6,5))),3),3),0) -> 0 | CQ8: =IF(CO8>CP8,"1",IF(CO8<CP8,"2","X")) -> X | CR8: =IF(CQ8=$H8,IF(CO8=$F8,IF(CP8=$G8,IF($F8-$G8>=3,6,IF($G8-$F8>=3,6,IF($F8+$G8>=4,6,5))),3),3),0) -> 0 | CU8: =IF(CS8>CT8,"1",IF(CS8<CT8,"2","X")) -> X | CV8: =IF(CU8=$H8,IF(CS8=$F8,IF(CT8=$G8,IF($F8-$G8>=3,6,IF($G8-$F8>=3,6,IF($F8+$G8>=4,6,5))),3),3),0) -> 0 | CY8: =IF(CW8>CX8,"1",IF(CW8<CX8,"2","X")) -> X | CZ8: =IF(CY8=$H8,IF(CW8=$F8,IF(CX8=$G8,IF($F8-$G8>=3,6,IF($G8-$F8>=3,6,IF($F8+$G8>=4,6,5))),3),3),0) -> 0 | DC8: =IF(DA8>DB8,"1",IF(DA8<DB8,"2","X")) -> X | DD8: =IF(DC8=$H8,IF(DA8=$F8,IF(DB8=$G8,IF($F8-$G8>=3,6,IF($G8-$F8>=3,6,IF($F8+$G8>=4,6,5))),3),3),0) -> 0 | DG8: =IF(DE8>DF8,"1",IF(DE8<DF8,"2","X")) -> X | DH8: =IF(DG8=$H8,IF(DE8=$F8,IF(DF8=$G8,IF($F8-$G8>=3,6,IF($G8-$F8>=3,6,IF($F8+$G8>=4,6,5))),3),3),0) -> 0 | DK8: =IF(DI8>DJ8,"1",IF(DI8<DJ8,"2","X")) -> X | DL8: =IF(DK8=$H8,IF(DI8=$F8,IF(DJ8=$G8,IF($F8-$G8>=3,6,IF($G8-$F8>=3,6,IF($F8+$G8>=4,6,5))),3),3),0) -> 0 | DO8: =IF(DM8>DN8,"1",IF(DM8<DN8,"2","X")) -> X | DP8: =IF(DO8=$H8,IF(DM8=$F8,IF(DN8=$G8,IF($F8-$G8>=3,6,IF($G8-$F8>=3,6,IF($F8+$G8>=4,6,5))),3),3),0) -> 0
A9: 44736 | B9: 05:00 | C9: South Africa | D9: South Korea | E9: =L9+P9+T9+X9+AB9+AF9+AJ9+AN9+AR9+AV9+AZ9+BD9+BH9+BL9+BP9+BT9+BX9+CB9+CF9+CJ9+CN9+CR9+CV9+CZ9+DD9+DH9+DL9 -> 0 | H9: =IF(ISNUMBER(F9),IF(F9>G9,"1",IF(F9<G9,"2","X"))) -> FALSE | K9: =IF(I9>J9,"1",IF(I9<J9,"2","X")) -> X | L9: =IF(K9=$H9,IF(I9=$F9,IF(J9=$G9,IF($F9-$G9>=3,6,IF($G9-$F9>=3,6,IF($F9+$G9>=4,6,5))),3),3),0) -> 0 | O9: =IF(M9>N9,"1",IF(M9<N9,"2","X")) -> X | P9: =IF(O9=$H9,IF(M9=$F9,IF(N9=$G9,IF($F9-$G9>=3,6,IF($G9-$F9>=3,6,IF($F9+$G9>=4,6,5))),3),3),0) -> 0 | S9: =IF(Q9>R9,"1",IF(Q9<R9,"2","X")) -> X | T9: =IF(S9=$H9,IF(Q9=$F9,IF(R9=$G9,IF($F9-$G9>=3,6,IF($G9-$F9>=3,6,IF($F9+$G9>=4,6,5))),3),3),0) -> 0 | W9: =IF(U9>V9,"1",IF(U9<V9,"2","X")) -> X | X9: =IF(W9=$H9,IF(U9=$F9,IF(V9=$G9,IF($F9-$G9>=3,6,IF($G9-$F9>=3,6,IF($F9+$G9>=4,6,5))),3),3),0) -> 0 | AA9: =IF(Y9>Z9,"1",IF(Y9<Z9,"2","X")) -> X | AB9: =IF(AA9=$H9,IF(Y9=$F9,IF(Z9=$G9,IF($F9-$G9>=3,6,IF($G9-$F9>=3,6,IF($F9+$G9>=4,6,5))),3),3),0) -> 0 | AE9: =IF(AC9>AD9,"1",IF(AC9<AD9,"2","X")) -> X | AF9: =IF(AE9=$H9,IF(AC9=$F9,IF(AD9=$G9,IF($F9-$G9>=3,6,IF($G9-$F9>=3,6,IF($F9+$G9>=4,6,5))),3),3),0) -> 0 | AI9: =IF(AG9>AH9,"1",IF(AG9<AH9,"2","X")) -> X | AJ9: =IF(AI9=$H9,IF(AG9=$F9,IF(AH9=$G9,IF($F9-$G9>=3,6,IF($G9-$F9>=3,6,IF($F9+$G9>=4,6,5))),3),3),0) -> 0 | AM9: =IF(AK9>AL9,"1",IF(AK9<AL9,"2","X")) -> X | AN9: =IF(AM9=$H9,IF(AK9=$F9,IF(AL9=$G9,IF($F9-$G9>=3,6,IF($G9-$F9>=3,6,IF($F9+$G9>=4,6,5))),3),3),0) -> 0 | AQ9: =IF(AO9>AP9,"1",IF(AO9<AP9,"2","X")) -> X | AR9: =IF(AQ9=$H9,IF(AO9=$F9,IF(AP9=$G9,IF($F9-$G9>=3,6,IF($G9-$F9>=3,6,IF($F9+$G9>=4,6,5))),3),3),0) -> 0 | AU9: =IF(AS9>AT9,"1",IF(AS9<AT9,"2","X")) -> X | AV9: =IF(AU9=$H9,IF(AS9=$F9,IF(AT9=$G9,IF($F9-$G9>=3,6,IF($G9-$F9>=3,6,IF($F9+$G9>=4,6,5))),3),3),0) -> 0 | AY9: =IF(AW9>AX9,"1",IF(AW9<AX9,"2","X")) -> X | AZ9: =IF(AY9=$H9,IF(AW9=$F9,IF(AX9=$G9,IF($F9-$G9>=3,6,IF($G9-$F9>=3,6,IF($F9+$G9>=4,6,5))),3),3),0) -> 0 | BC9: =IF(BA9>BB9,"1",IF(BA9<BB9,"2","X")) -> X | BD9: =IF(BC9=$H9,IF(BA9=$F9,IF(BB9=$G9,IF($F9-$G9>=3,6,IF($G9-$F9>=3,6,IF($F9+$G9>=4,6,5))),3),3),0) -> 0 | BG9: =IF(BE9>BF9,"1",IF(BE9<BF9,"2","X")) -> X | BH9: =IF(BG9=$H9,IF(BE9=$F9,IF(BF9=$G9,IF($F9-$G9>=3,6,IF($G9-$F9>=3,6,IF($F9+$G9>=4,6,5))),3),3),0) -> 0 | BK9: =IF(BI9>BJ9,"1",IF(BI9<BJ9,"2","X")) -> X | BL9: =IF(BK9=$H9,IF(BI9=$F9,IF(BJ9=$G9,IF($F9-$G9>=3,6,IF($G9-$F9>=3,6,IF($F9+$G9>=4,6,5))),3),3),0) -> 0 | BO9: =IF(BM9>BN9,"1",IF(BM9<BN9,"2","X")) -> X | BP9: =IF(BO9=$H9,IF(BM9=$F9,IF(BN9=$G9,IF($F9-$G9>=3,6,IF($G9-$F9>=3,6,IF($F9+$G9>=4,6,5))),3),3),0) -> 0 | BS9: =IF(BQ9>BR9,"1",IF(BQ9<BR9,"2","X")) -> X | BT9: =IF(BS9=$H9,IF(BQ9=$F9,IF(BR9=$G9,IF($F9-$G9>=3,6,IF($G9-$F9>=3,6,IF($F9+$G9>=4,6,5))),3),3),0) -> 0 | BW9: =IF(BU9>BV9,"1",IF(BU9<BV9,"2","X")) -> X | BX9: =IF(BW9=$H9,IF(BU9=$F9,IF(BV9=$G9,IF($F9-$G9>=3,6,IF($G9-$F9>=3,6,IF($F9+$G9>=4,6,5))),3),3),0) -> 0 | CA9: =IF(BY9>BZ9,"1",IF(BY9<BZ9,"2","X")) -> X | CB9: =IF(CA9=$H9,IF(BY9=$F9,IF(BZ9=$G9,IF($F9-$G9>=3,6,IF($G9-$F9>=3,6,IF($F9+$G9>=4,6,5))),3),3),0) -> 0 | CE9: =IF(CC9>CD9,"1",IF(CC9<CD9,"2","X")) -> X | CF9: =IF(CE9=$H9,IF(CC9=$F9,IF(CD9=$G9,IF($F9-$G9>=3,6,IF($G9-$F9>=3,6,IF($F9+$G9>=4,6,5))),3),3),0) -> 0 | CI9: =IF(CG9>CH9,"1",IF(CG9<CH9,"2","X")) -> X | CJ9: =IF(CI9=$H9,IF(CG9=$F9,IF(CH9=$G9,IF($F9-$G9>=3,6,IF($G9-$F9>=3,6,IF($F9+$G9>=4,6,5))),3),3),0) -> 0 | CM9: =IF(CK9>CL9,"1",IF(CK9<CL9,"2","X")) -> X | CN9: =IF(CM9=$H9,IF(CK9=$F9,IF(CL9=$G9,IF($F9-$G9>=3,6,IF($G9-$F9>=3,6,IF($F9+$G9>=4,6,5))),3),3),0) -> 0 | CQ9: =IF(CO9>CP9,"1",IF(CO9<CP9,"2","X")) -> X | CR9: =IF(CQ9=$H9,IF(CO9=$F9,IF(CP9=$G9,IF($F9-$G9>=3,6,IF($G9-$F9>=3,6,IF($F9+$G9>=4,6,5))),3),3),0) -> 0 | CU9: =IF(CS9>CT9,"1",IF(CS9<CT9,"2","X")) -> X | CV9: =IF(CU9=$H9,IF(CS9=$F9,IF(CT9=$G9,IF($F9-$G9>=3,6,IF($G9-$F9>=3,6,IF($F9+$G9>=4,6,5))),3),3),0) -> 0 | CY9: =IF(CW9>CX9,"1",IF(CW9<CX9,"2","X")) -> X | CZ9: =IF(CY9=$H9,IF(CW9=$F9,IF(CX9=$G9,IF($F9-$G9>=3,6,IF($G9-$F9>=3,6,IF($F9+$G9>=4,6,5))),3),3),0) -> 0 | DC9: =IF(DA9>DB9,"1",IF(DA9<DB9,"2","X")) -> X | DD9: =IF(DC9=$H9,IF(DA9=$F9,IF(DB9=$G9,IF($F9-$G9>=3,6,IF($G9-$F9>=3,6,IF($F9+$G9>=4,6,5))),3),3),0) -> 0 | DG9: =IF(DE9>DF9,"1",IF(DE9<DF9,"2","X")) -> X | DH9: =IF(DG9=$H9,IF(DE9=$F9,IF(DF9=$G9,IF($F9-$G9>=3,6,IF($G9-$F9>=3,6,IF($F9+$G9>=4,6,5))),3),3),0) -> 0 | DK9: =IF(DI9>DJ9,"1",IF(DI9<DJ9,"2","X")) -> X | DL9: =IF(DK9=$H9,IF(DI9=$F9,IF(DJ9=$G9,IF($F9-$G9>=3,6,IF($G9-$F9>=3,6,IF($F9+$G9>=4,6,5))),3),3),0) -> 0 | DO9: =IF(DM9>DN9,"1",IF(DM9<DN9,"2","X")) -> X | DP9: =IF(DO9=$H9,IF(DM9=$F9,IF(DN9=$G9,IF($F9-$G9>=3,6,IF($G9-$F9>=3,6,IF($F9+$G9>=4,6,5))),3),3),0) -> 0
A10: 44723 | B10: 23:00 | C10: Canada | D10: Bosnia and Herzegovina | E10: =L10+P10+T10+X10+AB10+AF10+AJ10+AN10+AR10+AV10+AZ10+BD10+BH10+BL10+BP10+BT10+BX10+CB10+CF10+CJ10+CN10+CR10+CV10+CZ10+DD10+DH10+DL10 -> 0 | H10: =IF(ISNUMBER(F10),IF(F10>G10,"1",IF(F10<G10,"2","X"))) -> FALSE | I10: 1 | J10: 1 | K10: =IF(I10>J10,"1",IF(I10<J10,"2","X")) -> X | L10: =IF(K10=$H10,IF(I10=$F10,IF(J10=$G10,IF($F10-$G10>=3,6,IF($G10-$F10>=3,6,IF($F10+$G10>=4,6,5))),3),3),0) -> 0 | M10: 2 | N10: 1 | O10: =IF(M10>N10,"1",IF(M10<N10,"2","X")) -> 1 | P10: =IF(O10=$H10,IF(M10=$F10,IF(N10=$G10,IF($F10-$G10>=3,6,IF($G10-$F10>=3,6,IF($F10+$G10>=4,6,5))),3),3),0) -> 0 | Q10: 2 | R10: 1 | S10: =IF(Q10>R10,"1",IF(Q10<R10,"2","X")) -> 1 | T10: =IF(S10=$H10,IF(Q10=$F10,IF(R10=$G10,IF($F10-$G10>=3,6,IF($G10-$F10>=3,6,IF($F10+$G10>=4,6,5))),3),3),0) -> 0 | U10: 1 | V10: 0 | W10: =IF(U10>V10,"1",IF(U10<V10,"2","X")) -> 1 | X10: =IF(W10=$H10,IF(U10=$F10,IF(V10=$G10,IF($F10-$G10>=3,6,IF($G10-$F10>=3,6,IF($F10+$G10>=4,6,5))),3),3),0) -> 0 | Y10: 1 | Z10: 1 | AA10: =IF(Y10>Z10,"1",IF(Y10<Z10,"2","X")) -> X | AB10: =IF(AA10=$H10,IF(Y10=$F10,IF(Z10=$G10,IF($F10-$G10>=3,6,IF($G10-$F10>=3,6,IF($F10+$G10>=4,6,5))),3),3),0) -> 0 | AC10: 1 | AD10: 2 | AE10: =IF(AC10>AD10,"1",IF(AC10<AD10,"2","X")) -> 2 | AF10: =IF(AE10=$H10,IF(AC10=$F10,IF(AD10=$G10,IF($F10-$G10>=3,6,IF($G10-$F10>=3,6,IF($F10+$G10>=4,6,5))),3),3),0) -> 0 | AG10: 2 | AH10: 2 | AI10: =IF(AG10>AH10,"1",IF(AG10<AH10,"2","X")) -> X | AJ10: =IF(AI10=$H10,IF(AG10=$F10,IF(AH10=$G10,IF($F10-$G10>=3,6,IF($G10-$F10>=3,6,IF($F10+$G10>=4,6,5))),3),3),0) -> 0 | AK10: 0 | AL10: 1 | AM10: =IF(AK10>AL10,"1",IF(AK10<AL10,"2","X")) -> 2 | AN10: =IF(AM10=$H10,IF(AK10=$F10,IF(AL10=$G10,IF($F10-$G10>=3,6,IF($G10-$F10>=3,6,IF($F10+$G10>=4,6,5))),3),3),0) -> 0 | AO10: 2 | AP10: 0 | AQ10: =IF(AO10>AP10,"1",IF(AO10<AP10,"2","X")) -> 1 | AR10: =IF(AQ10=$H10,IF(AO10=$F10,IF(AP10=$G10,IF($F10-$G10>=3,6,IF($G10-$F10>=3,6,IF($F10+$G10>=4,6,5))),3),3),0) -> 0 | AS10: 2 | AT10: 0 | AU10: =IF(AS10>AT10,"1",IF(AS10<AT10,"2","X")) -> 1 | AV10: =IF(AU10=$H10,IF(AS10=$F10,IF(AT10=$G10,IF($F10-$G10>=3,6,IF($G10-$F10>=3,6,IF($F10+$G10>=4,6,5))),3),3),0) -> 0 | AW10: 2 | AX10: 1 | AY10: =IF(AW10>AX10,"1",IF(AW10<AX10,"2","X")) -> 1 | AZ10: =IF(AY10=$H10,IF(AW10=$F10,IF(AX10=$G10,IF($F10-$G10>=3,6,IF($G10-$F10>=3,6,IF($F10+$G10>=4,6,5))),3),3),0) -> 0 | BA10: 1 | BB10: 0 | BC10: =IF(BA10>BB10,"1",IF(BA10<BB10,"2","X")) -> 1 | BD10: =IF(BC10=$H10,IF(BA10=$F10,IF(BB10=$G10,IF($F10-$G10>=3,6,IF($G10-$F10>=3,6,IF($F10+$G10>=4,6,5))),3),3),0) -> 0 | BE10: 0 | BF10: 2 | BG10: =IF(BE10>BF10,"1",IF(BE10<BF10,"2","X")) -> 2 | BH10: =IF(BG10=$H10,IF(BE10=$F10,IF(BF10=$G10,IF($F10-$G10>=3,6,IF($G10-$F10>=3,6,IF($F10+$G10>=4,6,5))),3),3),0) -> 0 | BI10: 2 | BJ10: 0 | BK10: =IF(BI10>BJ10,"1",IF(BI10<BJ10,"2","X")) -> 1 | BL10: =IF(BK10=$H10,IF(BI10=$F10,IF(BJ10=$G10,IF($F10-$G10>=3,6,IF($G10-$F10>=3,6,IF($F10+$G10>=4,6,5))),3),3),0) -> 0 | BM10: 2 | BN10: 1 | BO10: =IF(BM10>BN10,"1",IF(BM10<BN10,"2","X")) -> 1 | BP10: =IF(BO10=$H10,IF(BM10=$F10,IF(BN10=$G10,IF($F10-$G10>=3,6,IF($G10-$F10>=3,6,IF($F10+$G10>=4,6,5))),3),3),0) -> 0 | BQ10: 2 | BR10: 1 | BS10: =IF(BQ10>BR10,"1",IF(BQ10<BR10,"2","X")) -> 1 | BT10: =IF(BS10=$H10,IF(BQ10=$F10,IF(BR10=$G10,IF($F10-$G10>=3,6,IF($G10-$F10>=3,6,IF($F10+$G10>=4,6,5))),3),3),0) -> 0 | BU10: 2 | BV10: 0 | BW10: =IF(BU10>BV10,"1",IF(BU10<BV10,"2","X")) -> 1 | BX10: =IF(BW10=$H10,IF(BU10=$F10,IF(BV10=$G10,IF($F10-$G10>=3,6,IF($G10-$F10>=3,6,IF($F10+$G10>=4,6,5))),3),3),0) -> 0 | BY10: 1 | BZ10: 0 | CA10: =IF(BY10>BZ10,"1",IF(BY10<BZ10,"2","X")) -> 1 | CB10: =IF(CA10=$H10,IF(BY10=$F10,IF(BZ10=$G10,IF($F10-$G10>=3,6,IF($G10-$F10>=3,6,IF($F10+$G10>=4,6,5))),3),3),0) -> 0 | CC10: 1 | CD10: 0 | CE10: =IF(CC10>CD10,"1",IF(CC10<CD10,"2","X")) -> 1 | CF10: =IF(CE10=$H10,IF(CC10=$F10,IF(CD10=$G10,IF($F10-$G10>=3,6,IF($G10-$F10>=3,6,IF($F10+$G10>=4,6,5))),3),3),0) -> 0 | CG10: 2 | CH10: 0 | CI10: =IF(CG10>CH10,"1",IF(CG10<CH10,"2","X")) -> 1 | CJ10: =IF(CI10=$H10,IF(CG10=$F10,IF(CH10=$G10,IF($F10-$G10>=3,6,IF($G10-$F10>=3,6,IF($F10+$G10>=4,6,5))),3),3),0) -> 0 | CK10: 1 | CL10: 1 | CM10: =IF(CK10>CL10,"1",IF(CK10<CL10,"2","X")) -> X | CN10: =IF(CM10=$H10,IF(CK10=$F10,IF(CL10=$G10,IF($F10-$G10>=3,6,IF($G10-$F10>=3,6,IF($F10+$G10>=4,6,5))),3),3),0) -> 0 | CO10: 1 | CP10: 0 | CQ10: =IF(CO10>CP10,"1",IF(CO10<CP10,"2","X")) -> 1 | CR10: =IF(CQ10=$H10,IF(CO10=$F10,IF(CP10=$G10,IF($F10-$G10>=3,6,IF($G10-$F10>=3,6,IF($F10+$G10>=4,6,5))),3),3),0) -> 0 | CS10: 1 | CT10: 0 | CU10: =IF(CS10>CT10,"1",IF(CS10<CT10,"2","X")) -> 1 | CV10: =IF(CU10=$H10,IF(CS10=$F10,IF(CT10=$G10,IF($F10-$G10>=3,6,IF($G10-$F10>=3,6,IF($F10+$G10>=4,6,5))),3),3),0) -> 0 | CW10: 1 | CX10: 0 | CY10: =IF(CW10>CX10,"1",IF(CW10<CX10,"2","X")) -> 1 | CZ10: =IF(CY10=$H10,IF(CW10=$F10,IF(CX10=$G10,IF($F10-$G10>=3,6,IF($G10-$F10>=3,6,IF($F10+$G10>=4,6,5))),3),3),0) -> 0 | DA10: 2 | DB10: 1 | DC10: =IF(DA10>DB10,"1",IF(DA10<DB10,"2","X")) -> 1 | DD10: =IF(DC10=$H10,IF(DA10=$F10,IF(DB10=$G10,IF($F10-$G10>=3,6,IF($G10-$F10>=3,6,IF($F10+$G10>=4,6,5))),3),3),0) -> 0 | DE10: 1 | DF10: 1 | DG10: =IF(DE10>DF10,"1",IF(DE10<DF10,"2","X")) -> X | DH10: =IF(DG10=$H10,IF(DE10=$F10,IF(DF10=$G10,IF($F10-$G10>=3,6,IF($G10-$F10>=3,6,IF($F10+$G10>=4,6,5))),3),3),0) -> 0 | DI10: 1 | DJ10: 1 | DK10: =IF(DI10>DJ10,"1",IF(DI10<DJ10,"2","X")) -> X | DL10: =IF(DK10=$H10,IF(DI10=$F10,IF(DJ10=$G10,IF($F10-$G10>=3,6,IF($G10-$F10>=3,6,IF($F10+$G10>=4,6,5))),3),3),0) -> 0 | DM10: 2 | DN10: 2 | DO10: =IF(DM10>DN10,"1",IF(DM10<DN10,"2","X")) -> X | DP10: =IF(DO10=$H10,IF(DM10=$F10,IF(DN10=$G10,IF($F10-$G10>=3,6,IF($G10-$F10>=3,6,IF($F10+$G10>=4,6,5))),3),3),0) -> 0
A11: 44724 | B11: 23:00 | C11: Qatar | D11: Switzerland | E11: =L11+P11+T11+X11+AB11+AF11+AJ11+AN11+AR11+AV11+AZ11+BD11+BH11+BL11+BP11+BT11+BX11+CB11+CF11+CJ11+CN11+CR11+CV11+CZ11+DD11+DH11+DL11 -> 0 | H11: =IF(ISNUMBER(F11),IF(F11>G11,"1",IF(F11<G11,"2","X"))) -> FALSE | I11: 0 | J11: 2 | K11: =IF(I11>J11,"1",IF(I11<J11,"2","X")) -> 2 | L11: =IF(K11=$H11,IF(I11=$F11,IF(J11=$G11,IF($F11-$G11>=3,6,IF($G11-$F11>=3,6,IF($F11+$G11>=4,6,5))),3),3),0) -> 0 | M11: 0 | N11: 3 | O11: =IF(M11>N11,"1",IF(M11<N11,"2","X")) -> 2 | P11: =IF(O11=$H11,IF(M11=$F11,IF(N11=$G11,IF($F11-$G11>=3,6,IF($G11-$F11>=3,6,IF($F11+$G11>=4,6,5))),3),3),0) -> 0 | Q11: 0 | R11: 2 | S11: =IF(Q11>R11,"1",IF(Q11<R11,"2","X")) -> 2 | T11: =IF(S11=$H11,IF(Q11=$F11,IF(R11=$G11,IF($F11-$G11>=3,6,IF($G11-$F11>=3,6,IF($F11+$G11>=4,6,5))),3),3),0) -> 0 | U11: 0 | V11: 2 | W11: =IF(U11>V11,"1",IF(U11<V11,"2","X")) -> 2 | X11: =IF(W11=$H11,IF(U11=$F11,IF(V11=$G11,IF($F11-$G11>=3,6,IF($G11-$F11>=3,6,IF($F11+$G11>=4,6,5))),3),3),0) -> 0 | Y11: 1 | Z11: 4 | AA11: =IF(Y11>Z11,"1",IF(Y11<Z11,"2","X")) -> 2 | AB11: =IF(AA11=$H11,IF(Y11=$F11,IF(Z11=$G11,IF($F11-$G11>=3,6,IF($G11-$F11>=3,6,IF($F11+$G11>=4,6,5))),3),3),0) -> 0 | AC11: 0 | AD11: 2 | AE11: =IF(AC11>AD11,"1",IF(AC11<AD11,"2","X")) -> 2 | AF11: =IF(AE11=$H11,IF(AC11=$F11,IF(AD11=$G11,IF($F11-$G11>=3,6,IF($G11-$F11>=3,6,IF($F11+$G11>=4,6,5))),3),3),0) -> 0 | AG11: 0 | AH11: 2 | AI11: =IF(AG11>AH11,"1",IF(AG11<AH11,"2","X")) -> 2 | AJ11: =IF(AI11=$H11,IF(AG11=$F11,IF(AH11=$G11,IF($F11-$G11>=3,6,IF($G11-$F11>=3,6,IF($F11+$G11>=4,6,5))),3),3),0) -> 0 | AK11: 0 | AL11: 3 | AM11: =IF(AK11>AL11,"1",IF(AK11<AL11,"2","X")) -> 2 | AN11: =IF(AM11=$H11,IF(AK11=$F11,IF(AL11=$G11,IF($F11-$G11>=3,6,IF($G11-$F11>=3,6,IF($F11+$G11>=4,6,5))),3),3),0) -> 0 | AO11: 0 | AP11: 3 | AQ11: =IF(AO11>AP11,"1",IF(AO11<AP11,"2","X")) -> 2 | AR11: =IF(AQ11=$H11,IF(AO11=$F11,IF(AP11=$G11,IF($F11-$G11>=3,6,IF($G11-$F11>=3,6,IF($F11+$G11>=4,6,5))),3),3),0) -> 0 | AS11: 0 | AT11: 3 | AU11: =IF(AS11>AT11,"1",IF(AS11<AT11,"2","X")) -> 2 | AV11: =IF(AU11=$H11,IF(AS11=$F11,IF(AT11=$G11,IF($F11-$G11>=3,6,IF($G11-$F11>=3,6,IF($F11+$G11>=4,6,5))),3),3),0) -> 0 | AW11: 0 | AX11: 2 | AY11: =IF(AW11>AX11,"1",IF(AW11<AX11,"2","X")) -> 2 | AZ11: =IF(AY11=$H11,IF(AW11=$F11,IF(AX11=$G11,IF($F11-$G11>=3,6,IF($G11-$F11>=3,6,IF($F11+$G11>=4,6,5))),3),3),0) -> 0 | BA11: 0 | BB11: 2 | BC11: =IF(BA11>BB11,"1",IF(BA11<BB11,"2","X")) -> 2 | BD11: =IF(BC11=$H11,IF(BA11=$F11,IF(BB11=$G11,IF($F11-$G11>=3,6,IF($G11-$F11>=3,6,IF($F11+$G11>=4,6,5))),3),3),0) -> 0 | BE11: 0 | BF11: 1 | BG11: =IF(BE11>BF11,"1",IF(BE11<BF11,"2","X")) -> 2 | BH11: =IF(BG11=$H11,IF(BE11=$F11,IF(BF11=$G11,IF($F11-$G11>=3,6,IF($G11-$F11>=3,6,IF($F11+$G11>=4,6,5))),3),3),0) -> 0 | BI11: 0 | BJ11: 2 | BK11: =IF(BI11>BJ11,"1",IF(BI11<BJ11,"2","X")) -> 2 | BL11: =IF(BK11=$H11,IF(BI11=$F11,IF(BJ11=$G11,IF($F11-$G11>=3,6,IF($G11-$F11>=3,6,IF($F11+$G11>=4,6,5))),3),3),0) -> 0 | BM11: 0 | BN11: 2 | BO11: =IF(BM11>BN11,"1",IF(BM11<BN11,"2","X")) -> 2 | BP11: =IF(BO11=$H11,IF(BM11=$F11,IF(BN11=$G11,IF($F11-$G11>=3,6,IF($G11-$F11>=3,6,IF($F11+$G11>=4,6,5))),3),3),0) -> 0 | BQ11: 0 | BR11: 1 | BS11: =IF(BQ11>BR11,"1",IF(BQ11<BR11,"2","X")) -> 2 | BT11: =IF(BS11=$H11,IF(BQ11=$F11,IF(BR11=$G11,IF($F11-$G11>=3,6,IF($G11-$F11>=3,6,IF($F11+$G11>=4,6,5))),3),3),0) -> 0 | BU11: 0 | BV11: 2 | BW11: =IF(BU11>BV11,"1",IF(BU11<BV11,"2","X")) -> 2 | BX11: =IF(BW11=$H11,IF(BU11=$F11,IF(BV11=$G11,IF($F11-$G11>=3,6,IF($G11-$F11>=3,6,IF($F11+$G11>=4,6,5))),3),3),0) -> 0 | BY11: 0 | BZ11: 3 | CA11: =IF(BY11>BZ11,"1",IF(BY11<BZ11,"2","X")) -> 2 | CB11: =IF(CA11=$H11,IF(BY11=$F11,IF(BZ11=$G11,IF($F11-$G11>=3,6,IF($G11-$F11>=3,6,IF($F11+$G11>=4,6,5))),3),3),0) -> 0 | CC11: 1 | CD11: 3 | CE11: =IF(CC11>CD11,"1",IF(CC11<CD11,"2","X")) -> 2 | CF11: =IF(CE11=$H11,IF(CC11=$F11,IF(CD11=$G11,IF($F11-$G11>=3,6,IF($G11-$F11>=3,6,IF($F11+$G11>=4,6,5))),3),3),0) -> 0 | CG11: 0 | CH11: 2 | CI11: =IF(CG11>CH11,"1",IF(CG11<CH11,"2","X")) -> 2 | CJ11: =IF(CI11=$H11,IF(CG11=$F11,IF(CH11=$G11,IF($F11-$G11>=3,6,IF($G11-$F11>=3,6,IF($F11+$G11>=4,6,5))),3),3),0) -> 0 | CK11: 0 | CL11: 3 | CM11: =IF(CK11>CL11,"1",IF(CK11<CL11,"2","X")) -> 2 | CN11: =IF(CM11=$H11,IF(CK11=$F11,IF(CL11=$G11,IF($F11-$G11>=3,6,IF($G11-$F11>=3,6,IF($F11+$G11>=4,6,5))),3),3),0) -> 0 | CO11: 0 | CP11: 2 | CQ11: =IF(CO11>CP11,"1",IF(CO11<CP11,"2","X")) -> 2 | CR11: =IF(CQ11=$H11,IF(CO11=$F11,IF(CP11=$G11,IF($F11-$G11>=3,6,IF($G11-$F11>=3,6,IF($F11+$G11>=4,6,5))),3),3),0) -> 0 | CS11: 0 | CT11: 2 | CU11: =IF(CS11>CT11,"1",IF(CS11<CT11,"2","X")) -> 2 | CV11: =IF(CU11=$H11,IF(CS11=$F11,IF(CT11=$G11,IF($F11-$G11>=3,6,IF($G11-$F11>=3,6,IF($F11+$G11>=4,6,5))),3),3),0) -> 0 | CW11: 0 | CX11: 2 | CY11: =IF(CW11>CX11,"1",IF(CW11<CX11,"2","X")) -> 2 | CZ11: =IF(CY11=$H11,IF(CW11=$F11,IF(CX11=$G11,IF($F11-$G11>=3,6,IF($G11-$F11>=3,6,IF($F11+$G11>=4,6,5))),3),3),0) -> 0 | DA11: 0 | DB11: 3 | DC11: =IF(DA11>DB11,"1",IF(DA11<DB11,"2","X")) -> 2 | DD11: =IF(DC11=$H11,IF(DA11=$F11,IF(DB11=$G11,IF($F11-$G11>=3,6,IF($G11-$F11>=3,6,IF($F11+$G11>=4,6,5))),3),3),0) -> 0 | DE11: 0 | DF11: 2 | DG11: =IF(DE11>DF11,"1",IF(DE11<DF11,"2","X")) -> 2 | DH11: =IF(DG11=$H11,IF(DE11=$F11,IF(DF11=$G11,IF($F11-$G11>=3,6,IF($G11-$F11>=3,6,IF($F11+$G11>=4,6,5))),3),3),0) -> 0 | DI11: 0 | DJ11: 3 | DK11: =IF(DI11>DJ11,"1",IF(DI11<DJ11,"2","X")) -> 2 | DL11: =IF(DK11=$H11,IF(DI11=$F11,IF(DJ11=$G11,IF($F11-$G11>=3,6,IF($G11-$F11>=3,6,IF($F11+$G11>=4,6,5))),3),3),0) -> 0 | DM11: 0 | DN11: 2 | DO11: =IF(DM11>DN11,"1",IF(DM11<DN11,"2","X")) -> 2 | DP11: =IF(DO11=$H11,IF(DM11=$F11,IF(DN11=$G11,IF($F11-$G11>=3,6,IF($G11-$F11>=3,6,IF($F11+$G11>=4,6,5))),3),3),0) -> 0
